Watching for file changes with StatReloader
Watching for file changes with StatReloader
/home/peekay/Documents/projects/django/deploy/techV2/tech_investement/settings.py changed, reloading.
Watching for file changes with StatReloader
/home/peekay/Documents/projects/django/deploy/techV2/tech_investement/settings.py changed, reloading.
Watching for file changes with StatReloader
/home/peekay/Documents/projects/django/deploy/techV2/tech_investement/settings.py changed, reloading.
Watching for file changes with StatReloader
Not Found: /assets/FAXD.gif
Not Found: /dashboard/images/demo/pic2.jpg
Not Found: /dashboard/images/demo/pic3.jpg
Not Found: /dashboard/images/demo/pic1.jpg
Not Found: /dashboard/images/demo/pic4.jpg
Not Found: /dashboard/images/demo/pic6.jpg
Not Found: /dashboard/images/demo/pic7.jpg
Not Found: /dashboard/images/demo/pic5.jpg
Not Found: /dashboard/images/demo/pic8.jpg
Not Found: /favicon.ico
Not Found: /assets/FAXD.gif
Not Found: /dashboard/images/demo/pic1.jpg
Not Found: /dashboard/images/demo/pic4.jpg
Not Found: /dashboard/images/demo/pic2.jpg
Not Found: /dashboard/images/demo/pic3.jpg
Not Found: /dashboard/images/demo/pic7.jpg
Not Found: /dashboard/images/demo/pic6.jpg
Not Found: /dashboard/images/demo/pic5.jpg
Not Found: /dashboard/images/demo/pic8.jpg
/home/peekay/Documents/projects/django/deploy/techV2/investor/models.py changed, reloading.
Watching for file changes with StatReloader
/home/peekay/Documents/projects/django/deploy/techV2/investor/models.py changed, reloading.
Watching for file changes with StatReloader
/home/peekay/Documents/projects/django/deploy/techV2/investor/views.py changed, reloading.
Watching for file changes with StatReloader
/home/peekay/Documents/projects/django/deploy/techV2/investor/urls.py changed, reloading.
Watching for file changes with StatReloader
Not Found: /assets/FAXD.gif
Not Found: /dashboard/images/demo/pic1.jpg
Not Found: /dashboard/images/demo/pic2.jpg
Not Found: /dashboard/images/demo/pic3.jpg
Not Found: /dashboard/images/demo/pic5.jpg
Not Found: /dashboard/images/demo/pic6.jpg
Not Found: /dashboard/images/demo/pic4.jpg
Not Found: /dashboard/images/demo/pic7.jpg
Not Found: /dashboard/images/demo/pic8.jpg
Not Found: /favicon.ico
Not Found: /assets/FAXD.gif
Not Found: /dashboard/images/demo/pic1.jpg
Not Found: /dashboard/images/demo/pic5.jpg
Not Found: /dashboard/images/demo/pic4.jpg
Not Found: /dashboard/images/demo/pic2.jpg
Not Found: /dashboard/images/demo/pic3.jpg
Not Found: /dashboard/images/demo/pic8.jpg
Not Found: /dashboard/images/demo/pic6.jpg
Not Found: /dashboard/images/demo/pic7.jpg
Not Found: /favicon.ico
Not Found: /assets/FAXD.gif
Not Found: /dashboard/images/demo/pic1.jpg
Not Found: /dashboard/images/demo/pic2.jpg
Not Found: /dashboard/images/demo/pic4.jpg
Not Found: /dashboard/images/demo/pic3.jpg
Not Found: /dashboard/images/demo/pic6.jpg
Not Found: /dashboard/images/demo/pic5.jpg
Not Found: /dashboard/images/demo/pic7.jpg
Not Found: /dashboard/images/demo/pic8.jpg
Not Found: /favicon.ico
/home/peekay/Documents/projects/django/deploy/techV2/investor/models.py changed, reloading.
Watching for file changes with StatReloader
/home/peekay/Documents/projects/django/deploy/techV2/investor/views.py changed, reloading.
Watching for file changes with StatReloader
/home/peekay/Documents/projects/django/deploy/techV2/investor/views.py changed, reloading.
Watching for file changes with StatReloader
/home/peekay/Documents/projects/django/deploy/techV2/investor/views.py changed, reloading.
Watching for file changes with StatReloader
/home/peekay/Documents/projects/django/deploy/techV2/investor/urls.py changed, reloading.
Watching for file changes with StatReloader
/home/peekay/Documents/projects/django/deploy/techV2/investor/urls.py changed, reloading.
Watching for file changes with StatReloader
/home/peekay/Documents/projects/django/deploy/techV2/investor/urls.py changed, reloading.
Watching for file changes with StatReloader
/home/peekay/Documents/projects/django/deploy/techV2/investor/views.py changed, reloading.
Watching for file changes with StatReloader
Internal Server Error: /stkpush
Traceback (most recent call last):
  File "/home/peekay/Documents/projects/django/deploy/techV2/techv2-venv/lib/python3.10/site-packages/django/core/handlers/exception.py", line 55, in inner
    response = get_response(request)
  File "/home/peekay/Documents/projects/django/deploy/techV2/techv2-venv/lib/python3.10/site-packages/django/core/handlers/base.py", line 197, in _get_response
    response = wrapped_callback(request, *callback_args, **callback_kwargs)
  File "/home/peekay/Documents/projects/django/deploy/techV2/techv2-venv/lib/python3.10/site-packages/django/views/decorators/csrf.py", line 56, in wrapper_view
    return view_func(*args, **kwargs)
  File "/home/peekay/Documents/projects/django/deploy/techV2/investor/views.py", line 776, in init_stk
    access_token = get_access_token()
  File "/home/peekay/Documents/projects/django/deploy/techV2/investor/views.py", line 750, in get_access_token
    print(r.text.encode('utf8')['access_token'])
TypeError: byte indices must be integers or slices, not str
/home/peekay/Documents/projects/django/deploy/techV2/investor/views.py changed, reloading.
Watching for file changes with StatReloader
/home/peekay/Documents/projects/django/deploy/techV2/investor/views.py changed, reloading.
Watching for file changes with StatReloader
Not Found: /assets/FAXD.gif
Not Found: /dashboard/images/demo/pic1.jpg
Not Found: /dashboard/images/demo/pic2.jpg
Not Found: /dashboard/images/demo/pic3.jpg
Not Found: /dashboard/images/demo/pic4.jpg
Not Found: /dashboard/images/demo/pic6.jpg
Not Found: /dashboard/images/demo/pic5.jpg
Not Found: /dashboard/images/demo/pic7.jpg
Not Found: /dashboard/images/demo/pic8.jpg
/home/peekay/Documents/projects/django/deploy/techV2/investor/models.py changed, reloading.
Watching for file changes with StatReloader
/home/peekay/Documents/projects/django/deploy/techV2/investor/views.py changed, reloading.
Watching for file changes with StatReloader
/home/peekay/Documents/projects/django/deploy/techV2/investor/views.py changed, reloading.
Watching for file changes with StatReloader
Internal Server Error: /stkpush
Traceback (most recent call last):
  File "/home/peekay/Documents/projects/django/deploy/techV2/techv2-venv/lib/python3.10/site-packages/django/core/handlers/exception.py", line 55, in inner
    response = get_response(request)
  File "/home/peekay/Documents/projects/django/deploy/techV2/techv2-venv/lib/python3.10/site-packages/django/core/handlers/base.py", line 197, in _get_response
    response = wrapped_callback(request, *callback_args, **callback_kwargs)
  File "/home/peekay/Documents/projects/django/deploy/techV2/techv2-venv/lib/python3.10/site-packages/django/views/decorators/csrf.py", line 56, in wrapper_view
    return view_func(*args, **kwargs)
  File "/home/peekay/Documents/projects/django/deploy/techV2/investor/views.py", line 776, in init_stk
    access_token = get_access_token()
  File "/home/peekay/Documents/projects/django/deploy/techV2/investor/views.py", line 750, in get_access_token
    print(r.text.encode('utf8').access_token)
AttributeError: 'bytes' object has no attribute 'access_token'
/home/peekay/Documents/projects/django/deploy/techV2/investor/views.py changed, reloading.
Watching for file changes with StatReloader
/home/peekay/Documents/projects/django/deploy/techV2/investor/views.py changed, reloading.
Watching for file changes with StatReloader
/home/peekay/Documents/projects/django/deploy/techV2/investor/views.py changed, reloading.
Watching for file changes with StatReloader
/home/peekay/Documents/projects/django/deploy/techV2/investor/views.py changed, reloading.
Watching for file changes with StatReloader
/home/peekay/Documents/projects/django/deploy/techV2/investor/views.py changed, reloading.
Watching for file changes with StatReloader
Internal Server Error: /stkpush
Traceback (most recent call last):
  File "/home/peekay/Documents/projects/django/deploy/techV2/techv2-venv/lib/python3.10/site-packages/django/core/handlers/exception.py", line 55, in inner
    response = get_response(request)
  File "/home/peekay/Documents/projects/django/deploy/techV2/techv2-venv/lib/python3.10/site-packages/django/core/handlers/base.py", line 197, in _get_response
    response = wrapped_callback(request, *callback_args, **callback_kwargs)
  File "/home/peekay/Documents/projects/django/deploy/techV2/techv2-venv/lib/python3.10/site-packages/django/views/decorators/csrf.py", line 56, in wrapper_view
    return view_func(*args, **kwargs)
  File "/home/peekay/Documents/projects/django/deploy/techV2/investor/views.py", line 776, in init_stk
    access_token = get_access_token()
  File "/home/peekay/Documents/projects/django/deploy/techV2/investor/views.py", line 750, in get_access_token
    print(r.text.encode('utf8')["access_token"])
TypeError: byte indices must be integers or slices, not str
/home/peekay/Documents/projects/django/deploy/techV2/investor/views.py changed, reloading.
Watching for file changes with StatReloader
/home/peekay/Documents/projects/django/deploy/techV2/investor/views.py changed, reloading.
Watching for file changes with StatReloader
Internal Server Error: /stkpush
Traceback (most recent call last):
  File "/home/peekay/Documents/projects/django/deploy/techV2/techv2-venv/lib/python3.10/site-packages/django/core/handlers/exception.py", line 55, in inner
    response = get_response(request)
  File "/home/peekay/Documents/projects/django/deploy/techV2/techv2-venv/lib/python3.10/site-packages/django/core/handlers/base.py", line 197, in _get_response
    response = wrapped_callback(request, *callback_args, **callback_kwargs)
  File "/home/peekay/Documents/projects/django/deploy/techV2/techv2-venv/lib/python3.10/site-packages/django/views/decorators/csrf.py", line 56, in wrapper_view
    return view_func(*args, **kwargs)
  File "/home/peekay/Documents/projects/django/deploy/techV2/investor/views.py", line 777, in init_stk
    access_token = get_access_token()
  File "/home/peekay/Documents/projects/django/deploy/techV2/investor/views.py", line 751, in get_access_token
    print(r.get("access_token"))
AttributeError: 'Response' object has no attribute 'get'
/home/peekay/Documents/projects/django/deploy/techV2/investor/views.py changed, reloading.
Watching for file changes with StatReloader
/home/peekay/Documents/projects/django/deploy/techV2/investor/views.py changed, reloading.
Watching for file changes with StatReloader
Internal Server Error: /stkpush
Traceback (most recent call last):
  File "/home/peekay/Documents/projects/django/deploy/techV2/techv2-venv/lib/python3.10/site-packages/django/core/handlers/exception.py", line 55, in inner
    response = get_response(request)
  File "/home/peekay/Documents/projects/django/deploy/techV2/techv2-venv/lib/python3.10/site-packages/django/core/handlers/base.py", line 197, in _get_response
    response = wrapped_callback(request, *callback_args, **callback_kwargs)
  File "/home/peekay/Documents/projects/django/deploy/techV2/techv2-venv/lib/python3.10/site-packages/django/views/decorators/csrf.py", line 56, in wrapper_view
    return view_func(*args, **kwargs)
  File "/home/peekay/Documents/projects/django/deploy/techV2/investor/views.py", line 785, in init_stk
    access_token = get_access_token()
  File "/home/peekay/Documents/projects/django/deploy/techV2/investor/views.py", line 751, in get_access_token
    if response.status_code == 200:
NameError: name 'response' is not defined
/home/peekay/Documents/projects/django/deploy/techV2/investor/views.py changed, reloading.
Watching for file changes with StatReloader
/home/peekay/Documents/projects/django/deploy/techV2/investor/views.py changed, reloading.
Watching for file changes with StatReloader
/home/peekay/Documents/projects/django/deploy/techV2/investor/views.py changed, reloading.
Watching for file changes with StatReloader
/home/peekay/Documents/projects/django/deploy/techV2/investor/views.py changed, reloading.
Watching for file changes with StatReloader
Internal Server Error: /stkpush
Traceback (most recent call last):
  File "/home/peekay/Documents/projects/django/deploy/techV2/techv2-venv/lib/python3.10/site-packages/django/core/handlers/exception.py", line 55, in inner
    response = get_response(request)
  File "/home/peekay/Documents/projects/django/deploy/techV2/techv2-venv/lib/python3.10/site-packages/django/core/handlers/base.py", line 197, in _get_response
    response = wrapped_callback(request, *callback_args, **callback_kwargs)
  File "/home/peekay/Documents/projects/django/deploy/techV2/techv2-venv/lib/python3.10/site-packages/django/views/decorators/csrf.py", line 56, in wrapper_view
    return view_func(*args, **kwargs)
  File "/home/peekay/Documents/projects/django/deploy/techV2/investor/views.py", line 784, in init_stk
    access_token = get_access_token()
  File "/home/peekay/Documents/projects/django/deploy/techV2/investor/views.py", line 755, in get_access_token
    access_token = r.get("access_token")
AttributeError: 'Response' object has no attribute 'get'
Watching for file changes with StatReloader
Watching for file changes with StatReloader
Internal Server Error: /stkpush
Traceback (most recent call last):
  File "/home/peekay/Documents/projects/django/deploy/techV2/techv2-venv/lib/python3.10/site-packages/django/core/handlers/exception.py", line 55, in inner
    response = get_response(request)
  File "/home/peekay/Documents/projects/django/deploy/techV2/techv2-venv/lib/python3.10/site-packages/django/core/handlers/base.py", line 197, in _get_response
    response = wrapped_callback(request, *callback_args, **callback_kwargs)
  File "/home/peekay/Documents/projects/django/deploy/techV2/techv2-venv/lib/python3.10/site-packages/django/views/decorators/csrf.py", line 56, in wrapper_view
    return view_func(*args, **kwargs)
  File "/home/peekay/Documents/projects/django/deploy/techV2/investor/views.py", line 784, in init_stk
    access_token = get_access_token()
  File "/home/peekay/Documents/projects/django/deploy/techV2/investor/views.py", line 755, in get_access_token
    access_token = r.get("access_token")
AttributeError: 'Response' object has no attribute 'get'
/home/peekay/Documents/projects/django/deploy/techV2/investor/views.py changed, reloading.
Watching for file changes with StatReloader
/home/peekay/Documents/projects/django/deploy/techV2/investor/views.py changed, reloading.
Watching for file changes with StatReloader
Internal Server Error: /stkpush
Traceback (most recent call last):
  File "/home/peekay/Documents/projects/django/deploy/techV2/techv2-venv/lib/python3.10/site-packages/django/core/handlers/exception.py", line 55, in inner
    response = get_response(request)
  File "/home/peekay/Documents/projects/django/deploy/techV2/techv2-venv/lib/python3.10/site-packages/django/core/handlers/base.py", line 197, in _get_response
    response = wrapped_callback(request, *callback_args, **callback_kwargs)
  File "/home/peekay/Documents/projects/django/deploy/techV2/techv2-venv/lib/python3.10/site-packages/django/views/decorators/csrf.py", line 56, in wrapper_view
    return view_func(*args, **kwargs)
  File "/home/peekay/Documents/projects/django/deploy/techV2/investor/views.py", line 783, in init_stk
    access_token = get_access_token()
  File "/home/peekay/Documents/projects/django/deploy/techV2/investor/views.py", line 751, in get_access_token
    if response.status_code == 200:
NameError: name 'response' is not defined
Internal Server Error: /stkpush
Traceback (most recent call last):
  File "/home/peekay/Documents/projects/django/deploy/techV2/techv2-venv/lib/python3.10/site-packages/django/core/handlers/exception.py", line 55, in inner
    response = get_response(request)
  File "/home/peekay/Documents/projects/django/deploy/techV2/techv2-venv/lib/python3.10/site-packages/django/core/handlers/base.py", line 197, in _get_response
    response = wrapped_callback(request, *callback_args, **callback_kwargs)
  File "/home/peekay/Documents/projects/django/deploy/techV2/techv2-venv/lib/python3.10/site-packages/django/views/decorators/csrf.py", line 56, in wrapper_view
    return view_func(*args, **kwargs)
  File "/home/peekay/Documents/projects/django/deploy/techV2/investor/views.py", line 783, in init_stk
    access_token = get_access_token()
  File "/home/peekay/Documents/projects/django/deploy/techV2/investor/views.py", line 751, in get_access_token
    if response.status_code == 200:
NameError: name 'response' is not defined
/home/peekay/Documents/projects/django/deploy/techV2/investor/views.py changed, reloading.
Watching for file changes with StatReloader
Internal Server Error: /stkpush
Traceback (most recent call last):
  File "/home/peekay/Documents/projects/django/deploy/techV2/techv2-venv/lib/python3.10/site-packages/django/core/handlers/exception.py", line 55, in inner
    response = get_response(request)
  File "/home/peekay/Documents/projects/django/deploy/techV2/techv2-venv/lib/python3.10/site-packages/django/core/handlers/base.py", line 197, in _get_response
    response = wrapped_callback(request, *callback_args, **callback_kwargs)
  File "/home/peekay/Documents/projects/django/deploy/techV2/techv2-venv/lib/python3.10/site-packages/django/views/decorators/csrf.py", line 56, in wrapper_view
    return view_func(*args, **kwargs)
  File "/home/peekay/Documents/projects/django/deploy/techV2/investor/views.py", line 783, in init_stk
    access_token = get_access_token()
  File "/home/peekay/Documents/projects/django/deploy/techV2/investor/views.py", line 753, in get_access_token
    data = response.json()
NameError: name 'response' is not defined
/home/peekay/Documents/projects/django/deploy/techV2/investor/views.py changed, reloading.
Watching for file changes with StatReloader
Watching for file changes with StatReloader
/home/peekay/Documents/projects/django/deploy/techV2/tech_investement/settings.py changed, reloading.
Watching for file changes with StatReloader
/home/peekay/Documents/projects/django/deploy/techV2/tech_investement/settings.py changed, reloading.
Watching for file changes with StatReloader
Watching for file changes with StatReloader
/home/peekay/Documents/projects/django/deploy/techV2/investor/views.py changed, reloading.
Watching for file changes with StatReloader
Watching for file changes with StatReloader
/home/peekay/Documents/projects/django/deploy/techV2/investor/views.py changed, reloading.
Watching for file changes with StatReloader
/home/peekay/Documents/projects/django/deploy/techV2/investor/views.py changed, reloading.
Watching for file changes with StatReloader
/home/peekay/Documents/projects/django/deploy/techV2/investor/views.py changed, reloading.
Watching for file changes with StatReloader
/home/peekay/Documents/projects/django/deploy/techV2/investor/views.py changed, reloading.
Watching for file changes with StatReloader
/home/peekay/Documents/projects/django/deploy/techV2/investor/models.py changed, reloading.
Watching for file changes with StatReloader
/home/peekay/Documents/projects/django/deploy/techV2/investor/models.py changed, reloading.
Watching for file changes with StatReloader
/home/peekay/Documents/projects/django/deploy/techV2/investor/models.py changed, reloading.
Watching for file changes with StatReloader
/home/peekay/Documents/projects/django/deploy/techV2/investor/models.py changed, reloading.
Watching for file changes with StatReloader
/home/peekay/Documents/projects/django/deploy/techV2/investor/urls.py changed, reloading.
Watching for file changes with StatReloader
/home/peekay/Documents/projects/django/deploy/techV2/investor/views.py changed, reloading.
Watching for file changes with StatReloader
/home/peekay/Documents/projects/django/deploy/techV2/investor/views.py changed, reloading.
Watching for file changes with StatReloader
/home/peekay/Documents/projects/django/deploy/techV2/investor/views.py changed, reloading.
Watching for file changes with StatReloader
/home/peekay/Documents/projects/django/deploy/techV2/investor/views.py changed, reloading.
Watching for file changes with StatReloader
/home/peekay/Documents/projects/django/deploy/techV2/investor/views.py changed, reloading.
Watching for file changes with StatReloader
/home/peekay/Documents/projects/django/deploy/techV2/investor/views.py changed, reloading.
Watching for file changes with StatReloader
/home/peekay/Documents/projects/django/deploy/techV2/investor/views.py changed, reloading.
Watching for file changes with StatReloader
/home/peekay/Documents/projects/django/deploy/techV2/investor/views.py changed, reloading.
Watching for file changes with StatReloader
/home/peekay/Documents/projects/django/deploy/techV2/investor/views.py changed, reloading.
Watching for file changes with StatReloader
/home/peekay/Documents/projects/django/deploy/techV2/investor/urls.py changed, reloading.
Watching for file changes with StatReloader
/home/peekay/Documents/projects/django/deploy/techV2/investor/urls.py changed, reloading.
Watching for file changes with StatReloader
/home/peekay/Documents/projects/django/deploy/techV2/investor/urls.py changed, reloading.
Watching for file changes with StatReloader
/home/peekay/Documents/projects/django/deploy/techV2/investor/views.py changed, reloading.
Watching for file changes with StatReloader
/home/peekay/Documents/projects/django/deploy/techV2/investor/views.py changed, reloading.
Watching for file changes with StatReloader
/home/peekay/Documents/projects/django/deploy/techV2/investor/views.py changed, reloading.
Watching for file changes with StatReloader
/home/peekay/Documents/projects/django/deploy/techV2/investor/views.py changed, reloading.
Watching for file changes with StatReloader
/home/peekay/Documents/projects/django/deploy/techV2/investor/views.py changed, reloading.
Watching for file changes with StatReloader
/home/peekay/Documents/projects/django/deploy/techV2/investor/views.py changed, reloading.
Watching for file changes with StatReloader
/home/peekay/Documents/projects/django/deploy/techV2/investor/views.py changed, reloading.
Watching for file changes with StatReloader
/home/peekay/Documents/projects/django/deploy/techV2/investor/urls.py changed, reloading.
Watching for file changes with StatReloader
/home/peekay/Documents/projects/django/deploy/techV2/investor/urls.py changed, reloading.
Watching for file changes with StatReloader
Not Found: /check-payment-status
Not Found: /assets/FAXD.gif
Not Found: /dashboard/images/demo/pic2.jpg
Not Found: /dashboard/images/demo/pic6.jpg
Not Found: /dashboard/images/demo/pic5.jpg
Not Found: /dashboard/images/demo/pic1.jpg
Not Found: /dashboard/images/demo/pic3.jpg
Not Found: /dashboard/images/demo/pic4.jpg
Not Found: /dashboard/images/demo/pic7.jpg
Not Found: /dashboard/images/demo/pic8.jpg
Not Found: /assets/FAXD.gif
Not Found: /dashboard/images/demo/pic1.jpg
Not Found: /dashboard/images/demo/pic4.jpg
Not Found: /dashboard/images/demo/pic2.jpg
Not Found: /dashboard/images/demo/pic3.jpg
Not Found: /dashboard/images/demo/pic6.jpg
Not Found: /dashboard/images/demo/pic5.jpg
Not Found: /dashboard/images/demo/pic7.jpg
Not Found: /dashboard/images/demo/pic8.jpg
/home/peekay/Documents/projects/django/deploy/techV2/investor/admin.py changed, reloading.
Watching for file changes with StatReloader
/home/peekay/Documents/projects/django/deploy/techV2/investor/admin.py changed, reloading.
Watching for file changes with StatReloader
Internal Server Error: /admin/investor/mpesapayment/
Traceback (most recent call last):
  File "/home/peekay/Documents/projects/django/deploy/techV2/techv2-venv/lib/python3.10/site-packages/django/db/backends/utils.py", line 89, in _execute
    return self.cursor.execute(sql, params)
psycopg2.errors.UndefinedTable: relation "investor_mpesapayment" does not exist
LINE 1: SELECT COUNT(*) AS "__count" FROM "investor_mpesapayment"
                                          ^


The above exception was the direct cause of the following exception:

Traceback (most recent call last):
  File "/home/peekay/Documents/projects/django/deploy/techV2/techv2-venv/lib/python3.10/site-packages/django/core/handlers/exception.py", line 55, in inner
    response = get_response(request)
  File "/home/peekay/Documents/projects/django/deploy/techV2/techv2-venv/lib/python3.10/site-packages/django/core/handlers/base.py", line 197, in _get_response
    response = wrapped_callback(request, *callback_args, **callback_kwargs)
  File "/home/peekay/Documents/projects/django/deploy/techV2/techv2-venv/lib/python3.10/site-packages/django/contrib/admin/options.py", line 688, in wrapper
    return self.admin_site.admin_view(view)(*args, **kwargs)
  File "/home/peekay/Documents/projects/django/deploy/techV2/techv2-venv/lib/python3.10/site-packages/django/utils/decorators.py", line 134, in _wrapper_view
    response = view_func(request, *args, **kwargs)
  File "/home/peekay/Documents/projects/django/deploy/techV2/techv2-venv/lib/python3.10/site-packages/django/views/decorators/cache.py", line 62, in _wrapper_view_func
    response = view_func(request, *args, **kwargs)
  File "/home/peekay/Documents/projects/django/deploy/techV2/techv2-venv/lib/python3.10/site-packages/django/contrib/admin/sites.py", line 242, in inner
    return view(request, *args, **kwargs)
  File "/home/peekay/Documents/projects/django/deploy/techV2/techv2-venv/lib/python3.10/site-packages/django/utils/decorators.py", line 46, in _wrapper
    return bound_method(*args, **kwargs)
  File "/home/peekay/Documents/projects/django/deploy/techV2/techv2-venv/lib/python3.10/site-packages/django/utils/decorators.py", line 134, in _wrapper_view
    response = view_func(request, *args, **kwargs)
  File "/home/peekay/Documents/projects/django/deploy/techV2/techv2-venv/lib/python3.10/site-packages/django/contrib/admin/options.py", line 1926, in changelist_view
    cl = self.get_changelist_instance(request)
  File "/home/peekay/Documents/projects/django/deploy/techV2/techv2-venv/lib/python3.10/site-packages/django/contrib/admin/options.py", line 836, in get_changelist_instance
    return ChangeList(
  File "/home/peekay/Documents/projects/django/deploy/techV2/techv2-venv/lib/python3.10/site-packages/django/contrib/admin/views/main.py", line 123, in __init__
    self.get_results(request)
  File "/home/peekay/Documents/projects/django/deploy/techV2/techv2-venv/lib/python3.10/site-packages/django/contrib/admin/views/main.py", line 279, in get_results
    result_count = paginator.count
  File "/home/peekay/Documents/projects/django/deploy/techV2/techv2-venv/lib/python3.10/site-packages/django/utils/functional.py", line 57, in __get__
    res = instance.__dict__[self.name] = self.func(instance)
  File "/home/peekay/Documents/projects/django/deploy/techV2/techv2-venv/lib/python3.10/site-packages/django/core/paginator.py", line 93, in count
    return c()
  File "/home/peekay/Documents/projects/django/deploy/techV2/techv2-venv/lib/python3.10/site-packages/django/db/models/query.py", line 608, in count
    return self.query.get_count(using=self.db)
  File "/home/peekay/Documents/projects/django/deploy/techV2/techv2-venv/lib/python3.10/site-packages/django/db/models/sql/query.py", line 568, in get_count
    return obj.get_aggregation(using, {"__count": Count("*")})["__count"]
  File "/home/peekay/Documents/projects/django/deploy/techV2/techv2-venv/lib/python3.10/site-packages/django/db/models/sql/query.py", line 554, in get_aggregation
    result = compiler.execute_sql(SINGLE)
  File "/home/peekay/Documents/projects/django/deploy/techV2/techv2-venv/lib/python3.10/site-packages/django/db/models/sql/compiler.py", line 1562, in execute_sql
    cursor.execute(sql, params)
  File "/home/peekay/Documents/projects/django/deploy/techV2/techv2-venv/lib/python3.10/site-packages/django/db/backends/utils.py", line 102, in execute
    return super().execute(sql, params)
  File "/home/peekay/Documents/projects/django/deploy/techV2/techv2-venv/lib/python3.10/site-packages/django/db/backends/utils.py", line 67, in execute
    return self._execute_with_wrappers(
  File "/home/peekay/Documents/projects/django/deploy/techV2/techv2-venv/lib/python3.10/site-packages/django/db/backends/utils.py", line 80, in _execute_with_wrappers
    return executor(sql, params, many, context)
  File "/home/peekay/Documents/projects/django/deploy/techV2/techv2-venv/lib/python3.10/site-packages/django/db/backends/utils.py", line 84, in _execute
    with self.db.wrap_database_errors:
  File "/home/peekay/Documents/projects/django/deploy/techV2/techv2-venv/lib/python3.10/site-packages/django/db/utils.py", line 91, in __exit__
    raise dj_exc_value.with_traceback(traceback) from exc_value
  File "/home/peekay/Documents/projects/django/deploy/techV2/techv2-venv/lib/python3.10/site-packages/django/db/backends/utils.py", line 89, in _execute
    return self.cursor.execute(sql, params)
django.db.utils.ProgrammingError: relation "investor_mpesapayment" does not exist
LINE 1: SELECT COUNT(*) AS "__count" FROM "investor_mpesapayment"
                                          ^

Watching for file changes with StatReloader
Watching for file changes with StatReloader
Watching for file changes with StatReloader
/home/peekay/Documents/projects/django/deploy/techV2/investor/views.py changed, reloading.
Watching for file changes with StatReloader
/home/peekay/Documents/projects/django/deploy/techV2/investor/views.py changed, reloading.
Watching for file changes with StatReloader
Watching for file changes with StatReloader
/home/peekay/Documents/projects/django/deploy/techV2/investor/views.py changed, reloading.
Watching for file changes with StatReloader
Internal Server Error: /stkpush
Traceback (most recent call last):
  File "/home/peekay/Documents/projects/django/deploy/techV2/techv2-venv/lib/python3.10/site-packages/django/core/handlers/exception.py", line 55, in inner
    response = get_response(request)
  File "/home/peekay/Documents/projects/django/deploy/techV2/techv2-venv/lib/python3.10/site-packages/django/core/handlers/base.py", line 197, in _get_response
    response = wrapped_callback(request, *callback_args, **callback_kwargs)
  File "/home/peekay/Documents/projects/django/deploy/techV2/techv2-venv/lib/python3.10/site-packages/django/views/decorators/csrf.py", line 56, in wrapper_view
    return view_func(*args, **kwargs)
  File "/home/peekay/Documents/projects/django/deploy/techV2/investor/views.py", line 820, in init_stk
    access_token = _access_token()
NameError: name '_access_token' is not defined
/home/peekay/Documents/projects/django/deploy/techV2/investor/views.py changed, reloading.
Watching for file changes with StatReloader
Watching for file changes with StatReloader
/home/peekay/Documents/projects/django/deploy/techV2/investor/views.py changed, reloading.
Watching for file changes with StatReloader
/home/peekay/Documents/projects/django/deploy/techV2/investor/views.py changed, reloading.
Watching for file changes with StatReloader
Internal Server Error: /dashboard/
Traceback (most recent call last):
  File "/home/peekay/Documents/projects/django/deploy/techV2/techv2-venv/lib/python3.10/site-packages/django/core/handlers/exception.py", line 55, in inner
    response = get_response(request)
  File "/home/peekay/Documents/projects/django/deploy/techV2/techv2-venv/lib/python3.10/site-packages/django/core/handlers/base.py", line 197, in _get_response
    response = wrapped_callback(request, *callback_args, **callback_kwargs)
  File "/home/peekay/Documents/projects/django/deploy/techV2/techv2-venv/lib/python3.10/site-packages/django/contrib/auth/decorators.py", line 23, in _wrapper_view
    return view_func(request, *args, **kwargs)
  File "/home/peekay/Documents/projects/django/deploy/techV2/investor/views.py", line 135, in dashboard
    bonus = "{:,.2f}".format(UserAccount.objects.get(username=request.user).bonus)
  File "/home/peekay/Documents/projects/django/deploy/techV2/techv2-venv/lib/python3.10/site-packages/django/db/models/manager.py", line 87, in manager_method
    return getattr(self.get_queryset(), name)(*args, **kwargs)
  File "/home/peekay/Documents/projects/django/deploy/techV2/techv2-venv/lib/python3.10/site-packages/django/db/models/query.py", line 637, in get
    raise self.model.DoesNotExist(
investor.models.UserAccount.DoesNotExist: UserAccount matching query does not exist.
/home/peekay/Documents/projects/django/deploy/techV2/investor/views.py changed, reloading.
Watching for file changes with StatReloader
/home/peekay/Documents/projects/django/deploy/techV2/investor/views.py changed, reloading.
Watching for file changes with StatReloader
/home/peekay/Documents/projects/django/deploy/techV2/investor/views.py changed, reloading.
Watching for file changes with StatReloader
/home/peekay/Documents/projects/django/deploy/techV2/investor/views.py changed, reloading.
Watching for file changes with StatReloader
/home/peekay/Documents/projects/django/deploy/techV2/investor/views.py changed, reloading.
Watching for file changes with StatReloader
/home/peekay/Documents/projects/django/deploy/techV2/investor/views.py changed, reloading.
Watching for file changes with StatReloader
/home/peekay/Documents/projects/django/deploy/techV2/investor/views.py changed, reloading.
Watching for file changes with StatReloader
/home/peekay/Documents/projects/django/deploy/techV2/investor/views.py changed, reloading.
Watching for file changes with StatReloader
/home/peekay/Documents/projects/django/deploy/techV2/investor/views.py changed, reloading.
Watching for file changes with StatReloader
/home/peekay/Documents/projects/django/deploy/techV2/investor/urls.py changed, reloading.
Watching for file changes with StatReloader
/home/peekay/Documents/projects/django/deploy/techV2/investor/urls.py changed, reloading.
Watching for file changes with StatReloader
Internal Server Error: /dashboard/
Traceback (most recent call last):
  File "/home/peekay/Documents/projects/django/deploy/techV2/techv2-venv/lib/python3.10/site-packages/django/core/handlers/exception.py", line 55, in inner
    response = get_response(request)
  File "/home/peekay/Documents/projects/django/deploy/techV2/techv2-venv/lib/python3.10/site-packages/django/core/handlers/base.py", line 197, in _get_response
    response = wrapped_callback(request, *callback_args, **callback_kwargs)
  File "/home/peekay/Documents/projects/django/deploy/techV2/techv2-venv/lib/python3.10/site-packages/django/contrib/auth/decorators.py", line 23, in _wrapper_view
    return view_func(request, *args, **kwargs)
  File "/home/peekay/Documents/projects/django/deploy/techV2/investor/views.py", line 135, in dashboard
    bonus = "{:,.2f}".format(UserAccount.objects.get(username=request.user).bonus)
  File "/home/peekay/Documents/projects/django/deploy/techV2/techv2-venv/lib/python3.10/site-packages/django/db/models/manager.py", line 87, in manager_method
    return getattr(self.get_queryset(), name)(*args, **kwargs)
  File "/home/peekay/Documents/projects/django/deploy/techV2/techv2-venv/lib/python3.10/site-packages/django/db/models/query.py", line 637, in get
    raise self.model.DoesNotExist(
investor.models.UserAccount.DoesNotExist: UserAccount matching query does not exist.
Not Found: /assets/FAXD.gif
Not Found: /dashboard/images/demo/pic1.jpg
Not Found: /dashboard/images/demo/pic5.jpg
Not Found: /dashboard/images/demo/pic2.jpg
Not Found: /dashboard/images/demo/pic3.jpg
Not Found: /dashboard/images/demo/pic4.jpg
Not Found: /dashboard/images/demo/pic6.jpg
Not Found: /dashboard/images/demo/pic7.jpg
Not Found: /dashboard/images/demo/pic8.jpg
Watching for file changes with StatReloader
Watching for file changes with StatReloader
/home/peekay/Documents/projects/django/deploy/techV2/investor/models.py changed, reloading.
Watching for file changes with StatReloader
Watching for file changes with StatReloader
/home/peekay/Documents/projects/django/deploy/techV2/investor/urls.py changed, reloading.
Watching for file changes with StatReloader
/home/peekay/Documents/projects/django/deploy/techV2/investor/urls.py changed, reloading.
Watching for file changes with StatReloader
/home/peekay/Documents/projects/django/deploy/techV2/investor/views.py changed, reloading.
Watching for file changes with StatReloader
/home/peekay/Documents/projects/django/deploy/techV2/investor/views.py changed, reloading.
Watching for file changes with StatReloader
/home/peekay/Documents/projects/django/deploy/techV2/tech_investement/settings.py changed, reloading.
Watching for file changes with StatReloader
/home/peekay/Documents/projects/django/deploy/techV2/tech_investement/settings.py changed, reloading.
Watching for file changes with StatReloader
/home/peekay/Documents/projects/django/deploy/techV2/tech_investement/settings.py changed, reloading.
Watching for file changes with StatReloader
/home/peekay/Documents/projects/django/deploy/techV2/tech_investement/settings.py changed, reloading.
Watching for file changes with StatReloader
/home/peekay/Documents/projects/django/deploy/techV2/tech_investement/settings.py changed, reloading.
Watching for file changes with StatReloader
Watching for file changes with StatReloader
/home/peekay/Documents/projects/django/deploy/techV2/investor/views.py changed, reloading.
Watching for file changes with StatReloader
/home/peekay/Documents/projects/django/deploy/techV2/investor/views.py changed, reloading.
Watching for file changes with StatReloader
/home/peekay/Documents/projects/django/deploy/techV2/investor/views.py changed, reloading.
Watching for file changes with StatReloader
Not Found: /dashboard/images/demo/pic3.jpg
Not Found: /dashboard/images/demo/pic1.jpg
Not Found: /dashboard/images/demo/pic2.jpg
Not Found: /dashboard/images/demo/pic4.jpg
Not Found: /dashboard/images/demo/pic5.jpg
Not Found: /dashboard/images/demo/pic7.jpg
Not Found: /dashboard/images/demo/pic6.jpg
Not Found: /dashboard/images/demo/pic8.jpg
/home/peekay/Documents/projects/django/deploy/techV2/investor/views.py changed, reloading.
Watching for file changes with StatReloader
/home/peekay/Documents/projects/django/deploy/techV2/investor/views.py changed, reloading.
Watching for file changes with StatReloader
Internal Server Error: /stkpush
Traceback (most recent call last):
  File "/home/peekay/Documents/projects/django/deploy/techV2/techv2-venv/lib/python3.10/site-packages/django/core/handlers/exception.py", line 55, in inner
    response = get_response(request)
  File "/home/peekay/Documents/projects/django/deploy/techV2/techv2-venv/lib/python3.10/site-packages/django/core/handlers/base.py", line 197, in _get_response
    response = wrapped_callback(request, *callback_args, **callback_kwargs)
  File "/home/peekay/Documents/projects/django/deploy/techV2/techv2-venv/lib/python3.10/site-packages/django/contrib/auth/decorators.py", line 23, in _wrapper_view
    return view_func(request, *args, **kwargs)
  File "/home/peekay/Documents/projects/django/deploy/techV2/techv2-venv/lib/python3.10/site-packages/django/views/decorators/csrf.py", line 56, in wrapper_view
    return view_func(*args, **kwargs)
  File "/home/peekay/Documents/projects/django/deploy/techV2/investor/views.py", line 810, in init_stk
    user = request.get.user
AttributeError: 'WSGIRequest' object has no attribute 'get'
/home/peekay/Documents/projects/django/deploy/techV2/investor/views.py changed, reloading.
Watching for file changes with StatReloader
/home/peekay/Documents/projects/django/deploy/techV2/investor/views.py changed, reloading.
Watching for file changes with StatReloader
/home/peekay/Documents/projects/django/deploy/techV2/investor/models.py changed, reloading.
Watching for file changes with StatReloader
/home/peekay/Documents/projects/django/deploy/techV2/investor/views.py changed, reloading.
Watching for file changes with StatReloader
/home/peekay/Documents/projects/django/deploy/techV2/investor/models.py changed, reloading.
Watching for file changes with StatReloader
/home/peekay/Documents/projects/django/deploy/techV2/investor/models.py changed, reloading.
Watching for file changes with StatReloader
/home/peekay/Documents/projects/django/deploy/techV2/investor/models.py changed, reloading.
Watching for file changes with StatReloader
/home/peekay/Documents/projects/django/deploy/techV2/investor/models.py changed, reloading.
Watching for file changes with StatReloader
/home/peekay/Documents/projects/django/deploy/techV2/investor/views.py changed, reloading.
Watching for file changes with StatReloader
/home/peekay/Documents/projects/django/deploy/techV2/investor/views.py changed, reloading.
Watching for file changes with StatReloader
/home/peekay/Documents/projects/django/deploy/techV2/investor/views.py changed, reloading.
Watching for file changes with StatReloader
/home/peekay/Documents/projects/django/deploy/techV2/investor/models.py changed, reloading.
Watching for file changes with StatReloader
/home/peekay/Documents/projects/django/deploy/techV2/investor/views.py changed, reloading.
Watching for file changes with StatReloader
/home/peekay/Documents/projects/django/deploy/techV2/investor/views.py changed, reloading.
Watching for file changes with StatReloader
/home/peekay/Documents/projects/django/deploy/techV2/investor/views.py changed, reloading.
Watching for file changes with StatReloader
/home/peekay/Documents/projects/django/deploy/techV2/investor/views.py changed, reloading.
Watching for file changes with StatReloader
Internal Server Error: /stkpush
Traceback (most recent call last):
  File "/home/peekay/Documents/projects/django/deploy/techV2/techv2-venv/lib/python3.10/site-packages/django/db/backends/utils.py", line 89, in _execute
    return self.cursor.execute(sql, params)
psycopg2.errors.UndefinedTable: relation "investor_mpesarequest" does not exist
LINE 1: INSERT INTO "investor_mpesarequest" ("user", "amount", "phon...
                    ^


The above exception was the direct cause of the following exception:

Traceback (most recent call last):
  File "/home/peekay/Documents/projects/django/deploy/techV2/techv2-venv/lib/python3.10/site-packages/django/core/handlers/exception.py", line 55, in inner
    response = get_response(request)
  File "/home/peekay/Documents/projects/django/deploy/techV2/techv2-venv/lib/python3.10/site-packages/django/core/handlers/base.py", line 197, in _get_response
    response = wrapped_callback(request, *callback_args, **callback_kwargs)
  File "/home/peekay/Documents/projects/django/deploy/techV2/techv2-venv/lib/python3.10/site-packages/django/contrib/auth/decorators.py", line 23, in _wrapper_view
    return view_func(request, *args, **kwargs)
  File "/home/peekay/Documents/projects/django/deploy/techV2/techv2-venv/lib/python3.10/site-packages/django/views/decorators/csrf.py", line 56, in wrapper_view
    return view_func(*args, **kwargs)
  File "/home/peekay/Documents/projects/django/deploy/techV2/investor/views.py", line 813, in init_stk
    MpesaRequest.objects.create(
  File "/home/peekay/Documents/projects/django/deploy/techV2/techv2-venv/lib/python3.10/site-packages/django/db/models/manager.py", line 87, in manager_method
    return getattr(self.get_queryset(), name)(*args, **kwargs)
  File "/home/peekay/Documents/projects/django/deploy/techV2/techv2-venv/lib/python3.10/site-packages/django/db/models/query.py", line 658, in create
    obj.save(force_insert=True, using=self.db)
  File "/home/peekay/Documents/projects/django/deploy/techV2/techv2-venv/lib/python3.10/site-packages/django/db/models/base.py", line 814, in save
    self.save_base(
  File "/home/peekay/Documents/projects/django/deploy/techV2/techv2-venv/lib/python3.10/site-packages/django/db/models/base.py", line 877, in save_base
    updated = self._save_table(
  File "/home/peekay/Documents/projects/django/deploy/techV2/techv2-venv/lib/python3.10/site-packages/django/db/models/base.py", line 1020, in _save_table
    results = self._do_insert(
  File "/home/peekay/Documents/projects/django/deploy/techV2/techv2-venv/lib/python3.10/site-packages/django/db/models/base.py", line 1061, in _do_insert
    return manager._insert(
  File "/home/peekay/Documents/projects/django/deploy/techV2/techv2-venv/lib/python3.10/site-packages/django/db/models/manager.py", line 87, in manager_method
    return getattr(self.get_queryset(), name)(*args, **kwargs)
  File "/home/peekay/Documents/projects/django/deploy/techV2/techv2-venv/lib/python3.10/site-packages/django/db/models/query.py", line 1805, in _insert
    return query.get_compiler(using=using).execute_sql(returning_fields)
  File "/home/peekay/Documents/projects/django/deploy/techV2/techv2-venv/lib/python3.10/site-packages/django/db/models/sql/compiler.py", line 1822, in execute_sql
    cursor.execute(sql, params)
  File "/home/peekay/Documents/projects/django/deploy/techV2/techv2-venv/lib/python3.10/site-packages/django/db/backends/utils.py", line 102, in execute
    return super().execute(sql, params)
  File "/home/peekay/Documents/projects/django/deploy/techV2/techv2-venv/lib/python3.10/site-packages/django/db/backends/utils.py", line 67, in execute
    return self._execute_with_wrappers(
  File "/home/peekay/Documents/projects/django/deploy/techV2/techv2-venv/lib/python3.10/site-packages/django/db/backends/utils.py", line 80, in _execute_with_wrappers
    return executor(sql, params, many, context)
  File "/home/peekay/Documents/projects/django/deploy/techV2/techv2-venv/lib/python3.10/site-packages/django/db/backends/utils.py", line 84, in _execute
    with self.db.wrap_database_errors:
  File "/home/peekay/Documents/projects/django/deploy/techV2/techv2-venv/lib/python3.10/site-packages/django/db/utils.py", line 91, in __exit__
    raise dj_exc_value.with_traceback(traceback) from exc_value
  File "/home/peekay/Documents/projects/django/deploy/techV2/techv2-venv/lib/python3.10/site-packages/django/db/backends/utils.py", line 89, in _execute
    return self.cursor.execute(sql, params)
django.db.utils.ProgrammingError: relation "investor_mpesarequest" does not exist
LINE 1: INSERT INTO "investor_mpesarequest" ("user", "amount", "phon...
                    ^

Watching for file changes with StatReloader
Internal Server Error: /stkpush
Traceback (most recent call last):
  File "/home/peekay/Documents/projects/django/deploy/techV2/techv2-venv/lib/python3.10/site-packages/django/db/backends/utils.py", line 89, in _execute
    return self.cursor.execute(sql, params)
psycopg2.errors.StringDataRightTruncation: value too long for type character varying(20)


The above exception was the direct cause of the following exception:

Traceback (most recent call last):
  File "/home/peekay/Documents/projects/django/deploy/techV2/techv2-venv/lib/python3.10/site-packages/django/core/handlers/exception.py", line 55, in inner
    response = get_response(request)
  File "/home/peekay/Documents/projects/django/deploy/techV2/techv2-venv/lib/python3.10/site-packages/django/core/handlers/base.py", line 197, in _get_response
    response = wrapped_callback(request, *callback_args, **callback_kwargs)
  File "/home/peekay/Documents/projects/django/deploy/techV2/techv2-venv/lib/python3.10/site-packages/django/contrib/auth/decorators.py", line 23, in _wrapper_view
    return view_func(request, *args, **kwargs)
  File "/home/peekay/Documents/projects/django/deploy/techV2/techv2-venv/lib/python3.10/site-packages/django/views/decorators/csrf.py", line 56, in wrapper_view
    return view_func(*args, **kwargs)
  File "/home/peekay/Documents/projects/django/deploy/techV2/investor/views.py", line 813, in init_stk
    MpesaRequest.objects.create(
  File "/home/peekay/Documents/projects/django/deploy/techV2/techv2-venv/lib/python3.10/site-packages/django/db/models/manager.py", line 87, in manager_method
    return getattr(self.get_queryset(), name)(*args, **kwargs)
  File "/home/peekay/Documents/projects/django/deploy/techV2/techv2-venv/lib/python3.10/site-packages/django/db/models/query.py", line 658, in create
    obj.save(force_insert=True, using=self.db)
  File "/home/peekay/Documents/projects/django/deploy/techV2/techv2-venv/lib/python3.10/site-packages/django/db/models/base.py", line 814, in save
    self.save_base(
  File "/home/peekay/Documents/projects/django/deploy/techV2/techv2-venv/lib/python3.10/site-packages/django/db/models/base.py", line 877, in save_base
    updated = self._save_table(
  File "/home/peekay/Documents/projects/django/deploy/techV2/techv2-venv/lib/python3.10/site-packages/django/db/models/base.py", line 1020, in _save_table
    results = self._do_insert(
  File "/home/peekay/Documents/projects/django/deploy/techV2/techv2-venv/lib/python3.10/site-packages/django/db/models/base.py", line 1061, in _do_insert
    return manager._insert(
  File "/home/peekay/Documents/projects/django/deploy/techV2/techv2-venv/lib/python3.10/site-packages/django/db/models/manager.py", line 87, in manager_method
    return getattr(self.get_queryset(), name)(*args, **kwargs)
  File "/home/peekay/Documents/projects/django/deploy/techV2/techv2-venv/lib/python3.10/site-packages/django/db/models/query.py", line 1805, in _insert
    return query.get_compiler(using=using).execute_sql(returning_fields)
  File "/home/peekay/Documents/projects/django/deploy/techV2/techv2-venv/lib/python3.10/site-packages/django/db/models/sql/compiler.py", line 1822, in execute_sql
    cursor.execute(sql, params)
  File "/home/peekay/Documents/projects/django/deploy/techV2/techv2-venv/lib/python3.10/site-packages/django/db/backends/utils.py", line 102, in execute
    return super().execute(sql, params)
  File "/home/peekay/Documents/projects/django/deploy/techV2/techv2-venv/lib/python3.10/site-packages/django/db/backends/utils.py", line 67, in execute
    return self._execute_with_wrappers(
  File "/home/peekay/Documents/projects/django/deploy/techV2/techv2-venv/lib/python3.10/site-packages/django/db/backends/utils.py", line 80, in _execute_with_wrappers
    return executor(sql, params, many, context)
  File "/home/peekay/Documents/projects/django/deploy/techV2/techv2-venv/lib/python3.10/site-packages/django/db/backends/utils.py", line 84, in _execute
    with self.db.wrap_database_errors:
  File "/home/peekay/Documents/projects/django/deploy/techV2/techv2-venv/lib/python3.10/site-packages/django/db/utils.py", line 91, in __exit__
    raise dj_exc_value.with_traceback(traceback) from exc_value
  File "/home/peekay/Documents/projects/django/deploy/techV2/techv2-venv/lib/python3.10/site-packages/django/db/backends/utils.py", line 89, in _execute
    return self.cursor.execute(sql, params)
django.db.utils.DataError: value too long for type character varying(20)

/home/peekay/Documents/projects/django/deploy/techV2/investor/models.py changed, reloading.
Watching for file changes with StatReloader
/home/peekay/Documents/projects/django/deploy/techV2/investor/models.py changed, reloading.
Watching for file changes with StatReloader
Internal Server Error: /stkpush
Traceback (most recent call last):
  File "/home/peekay/Documents/projects/django/deploy/techV2/techv2-venv/lib/python3.10/site-packages/django/db/backends/utils.py", line 89, in _execute
    return self.cursor.execute(sql, params)
psycopg2.errors.StringDataRightTruncation: value too long for type character varying(20)


The above exception was the direct cause of the following exception:

Traceback (most recent call last):
  File "/home/peekay/Documents/projects/django/deploy/techV2/techv2-venv/lib/python3.10/site-packages/django/core/handlers/exception.py", line 55, in inner
    response = get_response(request)
  File "/home/peekay/Documents/projects/django/deploy/techV2/techv2-venv/lib/python3.10/site-packages/django/core/handlers/base.py", line 197, in _get_response
    response = wrapped_callback(request, *callback_args, **callback_kwargs)
  File "/home/peekay/Documents/projects/django/deploy/techV2/techv2-venv/lib/python3.10/site-packages/django/contrib/auth/decorators.py", line 23, in _wrapper_view
    return view_func(request, *args, **kwargs)
  File "/home/peekay/Documents/projects/django/deploy/techV2/techv2-venv/lib/python3.10/site-packages/django/views/decorators/csrf.py", line 56, in wrapper_view
    return view_func(*args, **kwargs)
  File "/home/peekay/Documents/projects/django/deploy/techV2/investor/views.py", line 813, in init_stk
    MpesaRequest.objects.create(
  File "/home/peekay/Documents/projects/django/deploy/techV2/techv2-venv/lib/python3.10/site-packages/django/db/models/manager.py", line 87, in manager_method
    return getattr(self.get_queryset(), name)(*args, **kwargs)
  File "/home/peekay/Documents/projects/django/deploy/techV2/techv2-venv/lib/python3.10/site-packages/django/db/models/query.py", line 658, in create
    obj.save(force_insert=True, using=self.db)
  File "/home/peekay/Documents/projects/django/deploy/techV2/techv2-venv/lib/python3.10/site-packages/django/db/models/base.py", line 814, in save
    self.save_base(
  File "/home/peekay/Documents/projects/django/deploy/techV2/techv2-venv/lib/python3.10/site-packages/django/db/models/base.py", line 877, in save_base
    updated = self._save_table(
  File "/home/peekay/Documents/projects/django/deploy/techV2/techv2-venv/lib/python3.10/site-packages/django/db/models/base.py", line 1020, in _save_table
    results = self._do_insert(
  File "/home/peekay/Documents/projects/django/deploy/techV2/techv2-venv/lib/python3.10/site-packages/django/db/models/base.py", line 1061, in _do_insert
    return manager._insert(
  File "/home/peekay/Documents/projects/django/deploy/techV2/techv2-venv/lib/python3.10/site-packages/django/db/models/manager.py", line 87, in manager_method
    return getattr(self.get_queryset(), name)(*args, **kwargs)
  File "/home/peekay/Documents/projects/django/deploy/techV2/techv2-venv/lib/python3.10/site-packages/django/db/models/query.py", line 1805, in _insert
    return query.get_compiler(using=using).execute_sql(returning_fields)
  File "/home/peekay/Documents/projects/django/deploy/techV2/techv2-venv/lib/python3.10/site-packages/django/db/models/sql/compiler.py", line 1822, in execute_sql
    cursor.execute(sql, params)
  File "/home/peekay/Documents/projects/django/deploy/techV2/techv2-venv/lib/python3.10/site-packages/django/db/backends/utils.py", line 102, in execute
    return super().execute(sql, params)
  File "/home/peekay/Documents/projects/django/deploy/techV2/techv2-venv/lib/python3.10/site-packages/django/db/backends/utils.py", line 67, in execute
    return self._execute_with_wrappers(
  File "/home/peekay/Documents/projects/django/deploy/techV2/techv2-venv/lib/python3.10/site-packages/django/db/backends/utils.py", line 80, in _execute_with_wrappers
    return executor(sql, params, many, context)
  File "/home/peekay/Documents/projects/django/deploy/techV2/techv2-venv/lib/python3.10/site-packages/django/db/backends/utils.py", line 84, in _execute
    with self.db.wrap_database_errors:
  File "/home/peekay/Documents/projects/django/deploy/techV2/techv2-venv/lib/python3.10/site-packages/django/db/utils.py", line 91, in __exit__
    raise dj_exc_value.with_traceback(traceback) from exc_value
  File "/home/peekay/Documents/projects/django/deploy/techV2/techv2-venv/lib/python3.10/site-packages/django/db/backends/utils.py", line 89, in _execute
    return self.cursor.execute(sql, params)
django.db.utils.DataError: value too long for type character varying(20)

Watching for file changes with StatReloader
Watching for file changes with StatReloader
/home/peekay/Documents/projects/django/deploy/techV2/investor/admin.py changed, reloading.
Watching for file changes with StatReloader
/home/peekay/Documents/projects/django/deploy/techV2/investor/admin.py changed, reloading.
Watching for file changes with StatReloader
Not Found: /favicon.ico
Internal Server Error: /admin/investor/mpesarequest/
Traceback (most recent call last):
  File "/home/peekay/Documents/projects/django/deploy/techV2/techv2-venv/lib/python3.10/site-packages/django/db/models/options.py", line 681, in get_field
    return self.fields_map[field_name]
KeyError: '__str__'

During handling of the above exception, another exception occurred:

Traceback (most recent call last):
  File "/home/peekay/Documents/projects/django/deploy/techV2/techv2-venv/lib/python3.10/site-packages/django/contrib/admin/utils.py", line 272, in lookup_field
    f = _get_non_gfk_field(opts, name)
  File "/home/peekay/Documents/projects/django/deploy/techV2/techv2-venv/lib/python3.10/site-packages/django/contrib/admin/utils.py", line 303, in _get_non_gfk_field
    field = opts.get_field(name)
  File "/home/peekay/Documents/projects/django/deploy/techV2/techv2-venv/lib/python3.10/site-packages/django/db/models/options.py", line 683, in get_field
    raise FieldDoesNotExist(
django.core.exceptions.FieldDoesNotExist: MpesaRequest has no field named '__str__'

During handling of the above exception, another exception occurred:

Traceback (most recent call last):
  File "/home/peekay/Documents/projects/django/deploy/techV2/techv2-venv/lib/python3.10/site-packages/django/core/handlers/exception.py", line 55, in inner
    response = get_response(request)
  File "/home/peekay/Documents/projects/django/deploy/techV2/techv2-venv/lib/python3.10/site-packages/django/core/handlers/base.py", line 220, in _get_response
    response = response.render()
  File "/home/peekay/Documents/projects/django/deploy/techV2/techv2-venv/lib/python3.10/site-packages/django/template/response.py", line 114, in render
    self.content = self.rendered_content
  File "/home/peekay/Documents/projects/django/deploy/techV2/techv2-venv/lib/python3.10/site-packages/django/template/response.py", line 92, in rendered_content
    return template.render(context, self._request)
  File "/home/peekay/Documents/projects/django/deploy/techV2/techv2-venv/lib/python3.10/site-packages/django/template/backends/django.py", line 61, in render
    return self.template.render(context)
  File "/home/peekay/Documents/projects/django/deploy/techV2/techv2-venv/lib/python3.10/site-packages/django/template/base.py", line 175, in render
    return self._render(context)
  File "/home/peekay/Documents/projects/django/deploy/techV2/techv2-venv/lib/python3.10/site-packages/django/template/base.py", line 167, in _render
    return self.nodelist.render(context)
  File "/home/peekay/Documents/projects/django/deploy/techV2/techv2-venv/lib/python3.10/site-packages/django/template/base.py", line 1005, in render
    return SafeString("".join([node.render_annotated(context) for node in self]))
  File "/home/peekay/Documents/projects/django/deploy/techV2/techv2-venv/lib/python3.10/site-packages/django/template/base.py", line 1005, in <listcomp>
    return SafeString("".join([node.render_annotated(context) for node in self]))
  File "/home/peekay/Documents/projects/django/deploy/techV2/techv2-venv/lib/python3.10/site-packages/django/template/base.py", line 966, in render_annotated
    return self.render(context)
  File "/home/peekay/Documents/projects/django/deploy/techV2/techv2-venv/lib/python3.10/site-packages/django/template/loader_tags.py", line 157, in render
    return compiled_parent._render(context)
  File "/home/peekay/Documents/projects/django/deploy/techV2/techv2-venv/lib/python3.10/site-packages/django/template/base.py", line 167, in _render
    return self.nodelist.render(context)
  File "/home/peekay/Documents/projects/django/deploy/techV2/techv2-venv/lib/python3.10/site-packages/django/template/base.py", line 1005, in render
    return SafeString("".join([node.render_annotated(context) for node in self]))
  File "/home/peekay/Documents/projects/django/deploy/techV2/techv2-venv/lib/python3.10/site-packages/django/template/base.py", line 1005, in <listcomp>
    return SafeString("".join([node.render_annotated(context) for node in self]))
  File "/home/peekay/Documents/projects/django/deploy/techV2/techv2-venv/lib/python3.10/site-packages/django/template/base.py", line 966, in render_annotated
    return self.render(context)
  File "/home/peekay/Documents/projects/django/deploy/techV2/techv2-venv/lib/python3.10/site-packages/django/template/loader_tags.py", line 157, in render
    return compiled_parent._render(context)
  File "/home/peekay/Documents/projects/django/deploy/techV2/techv2-venv/lib/python3.10/site-packages/django/template/base.py", line 167, in _render
    return self.nodelist.render(context)
  File "/home/peekay/Documents/projects/django/deploy/techV2/techv2-venv/lib/python3.10/site-packages/django/template/base.py", line 1005, in render
    return SafeString("".join([node.render_annotated(context) for node in self]))
  File "/home/peekay/Documents/projects/django/deploy/techV2/techv2-venv/lib/python3.10/site-packages/django/template/base.py", line 1005, in <listcomp>
    return SafeString("".join([node.render_annotated(context) for node in self]))
  File "/home/peekay/Documents/projects/django/deploy/techV2/techv2-venv/lib/python3.10/site-packages/django/template/base.py", line 966, in render_annotated
    return self.render(context)
  File "/home/peekay/Documents/projects/django/deploy/techV2/techv2-venv/lib/python3.10/site-packages/django/template/loader_tags.py", line 63, in render
    result = block.nodelist.render(context)
  File "/home/peekay/Documents/projects/django/deploy/techV2/techv2-venv/lib/python3.10/site-packages/django/template/base.py", line 1005, in render
    return SafeString("".join([node.render_annotated(context) for node in self]))
  File "/home/peekay/Documents/projects/django/deploy/techV2/techv2-venv/lib/python3.10/site-packages/django/template/base.py", line 1005, in <listcomp>
    return SafeString("".join([node.render_annotated(context) for node in self]))
  File "/home/peekay/Documents/projects/django/deploy/techV2/techv2-venv/lib/python3.10/site-packages/django/template/base.py", line 966, in render_annotated
    return self.render(context)
  File "/home/peekay/Documents/projects/django/deploy/techV2/techv2-venv/lib/python3.10/site-packages/django/template/loader_tags.py", line 63, in render
    result = block.nodelist.render(context)
  File "/home/peekay/Documents/projects/django/deploy/techV2/techv2-venv/lib/python3.10/site-packages/django/template/base.py", line 1005, in render
    return SafeString("".join([node.render_annotated(context) for node in self]))
  File "/home/peekay/Documents/projects/django/deploy/techV2/techv2-venv/lib/python3.10/site-packages/django/template/base.py", line 1005, in <listcomp>
    return SafeString("".join([node.render_annotated(context) for node in self]))
  File "/home/peekay/Documents/projects/django/deploy/techV2/techv2-venv/lib/python3.10/site-packages/django/template/base.py", line 966, in render_annotated
    return self.render(context)
  File "/home/peekay/Documents/projects/django/deploy/techV2/techv2-venv/lib/python3.10/site-packages/django/contrib/admin/templatetags/base.py", line 45, in render
    return super().render(context)
  File "/home/peekay/Documents/projects/django/deploy/techV2/techv2-venv/lib/python3.10/site-packages/django/template/library.py", line 258, in render
    _dict = self.func(*resolved_args, **resolved_kwargs)
  File "/home/peekay/Documents/projects/django/deploy/techV2/techv2-venv/lib/python3.10/site-packages/django/contrib/admin/templatetags/admin_list.py", line 336, in result_list
    "results": list(results(cl)),
  File "/home/peekay/Documents/projects/django/deploy/techV2/techv2-venv/lib/python3.10/site-packages/django/contrib/admin/templatetags/admin_list.py", line 312, in results
    yield ResultList(None, items_for_result(cl, res, None))
  File "/home/peekay/Documents/projects/django/deploy/techV2/techv2-venv/lib/python3.10/site-packages/django/contrib/admin/templatetags/admin_list.py", line 303, in __init__
    super().__init__(*items)
  File "/home/peekay/Documents/projects/django/deploy/techV2/techv2-venv/lib/python3.10/site-packages/django/contrib/admin/templatetags/admin_list.py", line 213, in items_for_result
    f, attr, value = lookup_field(field_name, result, cl.model_admin)
  File "/home/peekay/Documents/projects/django/deploy/techV2/techv2-venv/lib/python3.10/site-packages/django/contrib/admin/utils.py", line 285, in lookup_field
    value = attr()
  File "/home/peekay/Documents/projects/django/deploy/techV2/investor/models.py", line 208, in __str__
    return f"{self.reference} - {self.amount}"
AttributeError: 'MpesaRequest' object has no attribute 'reference'
/home/peekay/Documents/projects/django/deploy/techV2/investor/models.py changed, reloading.
Watching for file changes with StatReloader
/home/peekay/Documents/projects/django/deploy/techV2/investor/models.py changed, reloading.
Watching for file changes with StatReloader
Not Found: /favicon.ico
/home/peekay/Documents/projects/django/deploy/techV2/investor/views.py changed, reloading.
Watching for file changes with StatReloader
Watching for file changes with StatReloader
/home/peekay/Documents/projects/django/deploy/techV2/investor/views.py changed, reloading.
Watching for file changes with StatReloader
/home/peekay/Documents/projects/django/deploy/techV2/investor/views.py changed, reloading.
Watching for file changes with StatReloader
/home/peekay/Documents/projects/django/deploy/techV2/investor/views.py changed, reloading.
Watching for file changes with StatReloader
/home/peekay/Documents/projects/django/deploy/techV2/investor/urls.py changed, reloading.
Watching for file changes with StatReloader
/home/peekay/Documents/projects/django/deploy/techV2/investor/views.py changed, reloading.
Watching for file changes with StatReloader
/home/peekay/Documents/projects/django/deploy/techV2/investor/views.py changed, reloading.
Watching for file changes with StatReloader
/home/peekay/Documents/projects/django/deploy/techV2/investor/views.py changed, reloading.
Watching for file changes with StatReloader
Watching for file changes with StatReloader
/home/peekay/Documents/projects/django/deploy/techV2/investor/views.py changed, reloading.
Watching for file changes with StatReloader
Watching for file changes with StatReloader
Internal Server Error: /stkpush
Traceback (most recent call last):
  File "/home/peekay/Documents/projects/django/deploy/techV2/techv2-venv/lib/python3.10/site-packages/django/core/handlers/exception.py", line 55, in inner
    response = get_response(request)
  File "/home/peekay/Documents/projects/django/deploy/techV2/techv2-venv/lib/python3.10/site-packages/django/core/handlers/base.py", line 197, in _get_response
    response = wrapped_callback(request, *callback_args, **callback_kwargs)
  File "/home/peekay/Documents/projects/django/deploy/techV2/techv2-venv/lib/python3.10/site-packages/django/contrib/auth/decorators.py", line 23, in _wrapper_view
    return view_func(request, *args, **kwargs)
  File "/home/peekay/Documents/projects/django/deploy/techV2/techv2-venv/lib/python3.10/site-packages/django/views/decorators/csrf.py", line 56, in wrapper_view
    return view_func(*args, **kwargs)
  File "/home/peekay/Documents/projects/django/deploy/techV2/investor/views.py", line 810, in init_stk
    print(response["MerchantRequestID"])
KeyError: 'MerchantRequestID'
Internal Server Error: /stkpush
Traceback (most recent call last):
  File "/home/peekay/Documents/projects/django/deploy/techV2/techv2-venv/lib/python3.10/site-packages/django/core/handlers/exception.py", line 55, in inner
    response = get_response(request)
  File "/home/peekay/Documents/projects/django/deploy/techV2/techv2-venv/lib/python3.10/site-packages/django/core/handlers/base.py", line 197, in _get_response
    response = wrapped_callback(request, *callback_args, **callback_kwargs)
  File "/home/peekay/Documents/projects/django/deploy/techV2/techv2-venv/lib/python3.10/site-packages/django/contrib/auth/decorators.py", line 23, in _wrapper_view
    return view_func(request, *args, **kwargs)
  File "/home/peekay/Documents/projects/django/deploy/techV2/techv2-venv/lib/python3.10/site-packages/django/views/decorators/csrf.py", line 56, in wrapper_view
    return view_func(*args, **kwargs)
  File "/home/peekay/Documents/projects/django/deploy/techV2/investor/views.py", line 810, in init_stk
    print(response["MerchantRequestID"])
KeyError: 'MerchantRequestID'
Internal Server Error: /stkpush
Traceback (most recent call last):
  File "/home/peekay/Documents/projects/django/deploy/techV2/techv2-venv/lib/python3.10/site-packages/django/core/handlers/exception.py", line 55, in inner
    response = get_response(request)
  File "/home/peekay/Documents/projects/django/deploy/techV2/techv2-venv/lib/python3.10/site-packages/django/core/handlers/base.py", line 197, in _get_response
    response = wrapped_callback(request, *callback_args, **callback_kwargs)
  File "/home/peekay/Documents/projects/django/deploy/techV2/techv2-venv/lib/python3.10/site-packages/django/contrib/auth/decorators.py", line 23, in _wrapper_view
    return view_func(request, *args, **kwargs)
  File "/home/peekay/Documents/projects/django/deploy/techV2/techv2-venv/lib/python3.10/site-packages/django/views/decorators/csrf.py", line 56, in wrapper_view
    return view_func(*args, **kwargs)
  File "/home/peekay/Documents/projects/django/deploy/techV2/investor/views.py", line 810, in init_stk
    print(response["MerchantRequestID"])
KeyError: 'MerchantRequestID'
/home/peekay/Documents/projects/django/deploy/techV2/investor/views.py changed, reloading.
Watching for file changes with StatReloader
/home/peekay/Documents/projects/django/deploy/techV2/investor/views.py changed, reloading.
Watching for file changes with StatReloader
/home/peekay/Documents/projects/django/deploy/techV2/investor/views.py changed, reloading.
Watching for file changes with StatReloader
/home/peekay/Documents/projects/django/deploy/techV2/investor/views.py changed, reloading.
Watching for file changes with StatReloader
/home/peekay/Documents/projects/django/deploy/techV2/investor/views.py changed, reloading.
Watching for file changes with StatReloader
/home/peekay/Documents/projects/django/deploy/techV2/investor/views.py changed, reloading.
Watching for file changes with StatReloader
Internal Server Error: /stkpush
Traceback (most recent call last):
  File "/home/peekay/Documents/projects/django/deploy/techV2/techv2-venv/lib/python3.10/site-packages/django/core/handlers/exception.py", line 55, in inner
    response = get_response(request)
  File "/home/peekay/Documents/projects/django/deploy/techV2/techv2-venv/lib/python3.10/site-packages/django/core/handlers/base.py", line 197, in _get_response
    response = wrapped_callback(request, *callback_args, **callback_kwargs)
  File "/home/peekay/Documents/projects/django/deploy/techV2/techv2-venv/lib/python3.10/site-packages/django/contrib/auth/decorators.py", line 23, in _wrapper_view
    return view_func(request, *args, **kwargs)
  File "/home/peekay/Documents/projects/django/deploy/techV2/techv2-venv/lib/python3.10/site-packages/django/views/decorators/csrf.py", line 56, in wrapper_view
    return view_func(*args, **kwargs)
  File "/home/peekay/Documents/projects/django/deploy/techV2/investor/views.py", line 828, in init_stk
    description = response["errorMessage"],
KeyError: 'errorMessage'
Internal Server Error: /stkpush
Traceback (most recent call last):
  File "/home/peekay/Documents/projects/django/deploy/techV2/techv2-venv/lib/python3.10/site-packages/urllib3/connectionpool.py", line 793, in urlopen
    response = self._make_request(
  File "/home/peekay/Documents/projects/django/deploy/techV2/techv2-venv/lib/python3.10/site-packages/urllib3/connectionpool.py", line 537, in _make_request
    response = conn.getresponse()
  File "/home/peekay/Documents/projects/django/deploy/techV2/techv2-venv/lib/python3.10/site-packages/urllib3/connection.py", line 466, in getresponse
    httplib_response = super().getresponse()
  File "/usr/lib/python3.10/http/client.py", line 1375, in getresponse
    response.begin()
  File "/usr/lib/python3.10/http/client.py", line 318, in begin
    version, status, reason = self._read_status()
  File "/usr/lib/python3.10/http/client.py", line 287, in _read_status
    raise RemoteDisconnected("Remote end closed connection without"
http.client.RemoteDisconnected: Remote end closed connection without response

During handling of the above exception, another exception occurred:

Traceback (most recent call last):
  File "/home/peekay/Documents/projects/django/deploy/techV2/techv2-venv/lib/python3.10/site-packages/requests/adapters.py", line 667, in send
    resp = conn.urlopen(
  File "/home/peekay/Documents/projects/django/deploy/techV2/techv2-venv/lib/python3.10/site-packages/urllib3/connectionpool.py", line 847, in urlopen
    retries = retries.increment(
  File "/home/peekay/Documents/projects/django/deploy/techV2/techv2-venv/lib/python3.10/site-packages/urllib3/util/retry.py", line 470, in increment
    raise reraise(type(error), error, _stacktrace)
  File "/home/peekay/Documents/projects/django/deploy/techV2/techv2-venv/lib/python3.10/site-packages/urllib3/util/util.py", line 38, in reraise
    raise value.with_traceback(tb)
  File "/home/peekay/Documents/projects/django/deploy/techV2/techv2-venv/lib/python3.10/site-packages/urllib3/connectionpool.py", line 793, in urlopen
    response = self._make_request(
  File "/home/peekay/Documents/projects/django/deploy/techV2/techv2-venv/lib/python3.10/site-packages/urllib3/connectionpool.py", line 537, in _make_request
    response = conn.getresponse()
  File "/home/peekay/Documents/projects/django/deploy/techV2/techv2-venv/lib/python3.10/site-packages/urllib3/connection.py", line 466, in getresponse
    httplib_response = super().getresponse()
  File "/usr/lib/python3.10/http/client.py", line 1375, in getresponse
    response.begin()
  File "/usr/lib/python3.10/http/client.py", line 318, in begin
    version, status, reason = self._read_status()
  File "/usr/lib/python3.10/http/client.py", line 287, in _read_status
    raise RemoteDisconnected("Remote end closed connection without"
urllib3.exceptions.ProtocolError: ('Connection aborted.', RemoteDisconnected('Remote end closed connection without response'))

During handling of the above exception, another exception occurred:

Traceback (most recent call last):
  File "/home/peekay/Documents/projects/django/deploy/techV2/techv2-venv/lib/python3.10/site-packages/django/core/handlers/exception.py", line 55, in inner
    response = get_response(request)
  File "/home/peekay/Documents/projects/django/deploy/techV2/techv2-venv/lib/python3.10/site-packages/django/core/handlers/base.py", line 197, in _get_response
    response = wrapped_callback(request, *callback_args, **callback_kwargs)
  File "/home/peekay/Documents/projects/django/deploy/techV2/techv2-venv/lib/python3.10/site-packages/django/contrib/auth/decorators.py", line 23, in _wrapper_view
    return view_func(request, *args, **kwargs)
  File "/home/peekay/Documents/projects/django/deploy/techV2/techv2-venv/lib/python3.10/site-packages/django/views/decorators/csrf.py", line 56, in wrapper_view
    return view_func(*args, **kwargs)
  File "/home/peekay/Documents/projects/django/deploy/techV2/investor/views.py", line 783, in init_stk
    access_token = get_access_token()
  File "/home/peekay/Documents/projects/django/deploy/techV2/investor/views.py", line 749, in get_access_token
    r = requests.get(endpoint, auth=HTTPBasicAuth(consumer_key, consumer_secret))
  File "/home/peekay/Documents/projects/django/deploy/techV2/techv2-venv/lib/python3.10/site-packages/requests/api.py", line 73, in get
    return request("get", url, params=params, **kwargs)
  File "/home/peekay/Documents/projects/django/deploy/techV2/techv2-venv/lib/python3.10/site-packages/requests/api.py", line 59, in request
    return session.request(method=method, url=url, **kwargs)
  File "/home/peekay/Documents/projects/django/deploy/techV2/techv2-venv/lib/python3.10/site-packages/requests/sessions.py", line 589, in request
    resp = self.send(prep, **send_kwargs)
  File "/home/peekay/Documents/projects/django/deploy/techV2/techv2-venv/lib/python3.10/site-packages/requests/sessions.py", line 703, in send
    r = adapter.send(request, **kwargs)
  File "/home/peekay/Documents/projects/django/deploy/techV2/techv2-venv/lib/python3.10/site-packages/requests/adapters.py", line 682, in send
    raise ConnectionError(err, request=request)
requests.exceptions.ConnectionError: ('Connection aborted.', RemoteDisconnected('Remote end closed connection without response'))
/home/peekay/Documents/projects/django/deploy/techV2/investor/views.py changed, reloading.
Watching for file changes with StatReloader
Internal Server Error: /stkpush
Traceback (most recent call last):
  File "/home/peekay/Documents/projects/django/deploy/techV2/techv2-venv/lib/python3.10/site-packages/django/core/handlers/exception.py", line 55, in inner
    response = get_response(request)
  File "/home/peekay/Documents/projects/django/deploy/techV2/techv2-venv/lib/python3.10/site-packages/django/core/handlers/base.py", line 197, in _get_response
    response = wrapped_callback(request, *callback_args, **callback_kwargs)
  File "/home/peekay/Documents/projects/django/deploy/techV2/techv2-venv/lib/python3.10/site-packages/django/contrib/auth/decorators.py", line 23, in _wrapper_view
    return view_func(request, *args, **kwargs)
  File "/home/peekay/Documents/projects/django/deploy/techV2/techv2-venv/lib/python3.10/site-packages/django/views/decorators/csrf.py", line 56, in wrapper_view
    return view_func(*args, **kwargs)
  File "/home/peekay/Documents/projects/django/deploy/techV2/investor/views.py", line 828, in init_stk
    description = response["errorMessage"],
KeyError: 'errorMessage'
Internal Server Error: /stkpush
Traceback (most recent call last):
  File "/home/peekay/Documents/projects/django/deploy/techV2/techv2-venv/lib/python3.10/site-packages/django/core/handlers/exception.py", line 55, in inner
    response = get_response(request)
  File "/home/peekay/Documents/projects/django/deploy/techV2/techv2-venv/lib/python3.10/site-packages/django/core/handlers/base.py", line 197, in _get_response
    response = wrapped_callback(request, *callback_args, **callback_kwargs)
  File "/home/peekay/Documents/projects/django/deploy/techV2/techv2-venv/lib/python3.10/site-packages/django/contrib/auth/decorators.py", line 23, in _wrapper_view
    return view_func(request, *args, **kwargs)
  File "/home/peekay/Documents/projects/django/deploy/techV2/techv2-venv/lib/python3.10/site-packages/django/views/decorators/csrf.py", line 56, in wrapper_view
    return view_func(*args, **kwargs)
  File "/home/peekay/Documents/projects/django/deploy/techV2/investor/views.py", line 828, in init_stk
    description = response["errorMessage"],
KeyError: 'errorMessage'
Internal Server Error: /stkpush
Traceback (most recent call last):
  File "/home/peekay/Documents/projects/django/deploy/techV2/techv2-venv/lib/python3.10/site-packages/django/core/handlers/exception.py", line 55, in inner
    response = get_response(request)
  File "/home/peekay/Documents/projects/django/deploy/techV2/techv2-venv/lib/python3.10/site-packages/django/core/handlers/base.py", line 197, in _get_response
    response = wrapped_callback(request, *callback_args, **callback_kwargs)
  File "/home/peekay/Documents/projects/django/deploy/techV2/techv2-venv/lib/python3.10/site-packages/django/contrib/auth/decorators.py", line 23, in _wrapper_view
    return view_func(request, *args, **kwargs)
  File "/home/peekay/Documents/projects/django/deploy/techV2/techv2-venv/lib/python3.10/site-packages/django/views/decorators/csrf.py", line 56, in wrapper_view
    return view_func(*args, **kwargs)
  File "/home/peekay/Documents/projects/django/deploy/techV2/investor/views.py", line 828, in init_stk
    description = response["errorMessage"],
KeyError: 'errorMessage'
Internal Server Error: /stkpush
Traceback (most recent call last):
  File "/home/peekay/Documents/projects/django/deploy/techV2/techv2-venv/lib/python3.10/site-packages/django/core/handlers/exception.py", line 55, in inner
    response = get_response(request)
  File "/home/peekay/Documents/projects/django/deploy/techV2/techv2-venv/lib/python3.10/site-packages/django/core/handlers/base.py", line 197, in _get_response
    response = wrapped_callback(request, *callback_args, **callback_kwargs)
  File "/home/peekay/Documents/projects/django/deploy/techV2/techv2-venv/lib/python3.10/site-packages/django/contrib/auth/decorators.py", line 23, in _wrapper_view
    return view_func(request, *args, **kwargs)
  File "/home/peekay/Documents/projects/django/deploy/techV2/techv2-venv/lib/python3.10/site-packages/django/views/decorators/csrf.py", line 56, in wrapper_view
    return view_func(*args, **kwargs)
  File "/home/peekay/Documents/projects/django/deploy/techV2/investor/views.py", line 814, in init_stk
    if response["ResponseCode"] == 0:
KeyError: 'ResponseCode'
/home/peekay/Documents/projects/django/deploy/techV2/investor/views.py changed, reloading.
Watching for file changes with StatReloader
Internal Server Error: /stkpush
Traceback (most recent call last):
  File "/home/peekay/Documents/projects/django/deploy/techV2/techv2-venv/lib/python3.10/site-packages/django/core/handlers/exception.py", line 55, in inner
    response = get_response(request)
  File "/home/peekay/Documents/projects/django/deploy/techV2/techv2-venv/lib/python3.10/site-packages/django/core/handlers/base.py", line 197, in _get_response
    response = wrapped_callback(request, *callback_args, **callback_kwargs)
  File "/home/peekay/Documents/projects/django/deploy/techV2/techv2-venv/lib/python3.10/site-packages/django/contrib/auth/decorators.py", line 23, in _wrapper_view
    return view_func(request, *args, **kwargs)
  File "/home/peekay/Documents/projects/django/deploy/techV2/techv2-venv/lib/python3.10/site-packages/django/views/decorators/csrf.py", line 56, in wrapper_view
    return view_func(*args, **kwargs)
  File "/home/peekay/Documents/projects/django/deploy/techV2/investor/views.py", line 810, in init_stk
    print(response["MerchantRequestID"])
KeyError: 'MerchantRequestID'
/home/peekay/Documents/projects/django/deploy/techV2/investor/views.py changed, reloading.
Watching for file changes with StatReloader
Internal Server Error: /stkpush
Traceback (most recent call last):
  File "/home/peekay/Documents/projects/django/deploy/techV2/techv2-venv/lib/python3.10/site-packages/django/core/handlers/exception.py", line 55, in inner
    response = get_response(request)
  File "/home/peekay/Documents/projects/django/deploy/techV2/techv2-venv/lib/python3.10/site-packages/django/core/handlers/base.py", line 197, in _get_response
    response = wrapped_callback(request, *callback_args, **callback_kwargs)
  File "/home/peekay/Documents/projects/django/deploy/techV2/techv2-venv/lib/python3.10/site-packages/django/contrib/auth/decorators.py", line 23, in _wrapper_view
    return view_func(request, *args, **kwargs)
  File "/home/peekay/Documents/projects/django/deploy/techV2/techv2-venv/lib/python3.10/site-packages/django/views/decorators/csrf.py", line 56, in wrapper_view
    return view_func(*args, **kwargs)
  File "/home/peekay/Documents/projects/django/deploy/techV2/investor/views.py", line 814, in init_stk
    if response["ResponseCode"] == 0:
KeyError: 'ResponseCode'
/home/peekay/Documents/projects/django/deploy/techV2/investor/views.py changed, reloading.
Watching for file changes with StatReloader
Internal Server Error: /stkpush
Traceback (most recent call last):
  File "/home/peekay/Documents/projects/django/deploy/techV2/techv2-venv/lib/python3.10/site-packages/django/core/handlers/exception.py", line 55, in inner
    response = get_response(request)
  File "/home/peekay/Documents/projects/django/deploy/techV2/techv2-venv/lib/python3.10/site-packages/django/core/handlers/base.py", line 197, in _get_response
    response = wrapped_callback(request, *callback_args, **callback_kwargs)
  File "/home/peekay/Documents/projects/django/deploy/techV2/techv2-venv/lib/python3.10/site-packages/django/contrib/auth/decorators.py", line 23, in _wrapper_view
    return view_func(request, *args, **kwargs)
  File "/home/peekay/Documents/projects/django/deploy/techV2/techv2-venv/lib/python3.10/site-packages/django/views/decorators/csrf.py", line 56, in wrapper_view
    return view_func(*args, **kwargs)
  File "/home/peekay/Documents/projects/django/deploy/techV2/investor/views.py", line 814, in init_stk
    if response["ResponseCode"]:
KeyError: 'ResponseCode'
/home/peekay/Documents/projects/django/deploy/techV2/investor/views.py changed, reloading.
Watching for file changes with StatReloader
Internal Server Error: /stkpush
Traceback (most recent call last):
  File "/home/peekay/Documents/projects/django/deploy/techV2/techv2-venv/lib/python3.10/site-packages/django/core/handlers/exception.py", line 55, in inner
    response = get_response(request)
  File "/home/peekay/Documents/projects/django/deploy/techV2/techv2-venv/lib/python3.10/site-packages/django/core/handlers/base.py", line 197, in _get_response
    response = wrapped_callback(request, *callback_args, **callback_kwargs)
  File "/home/peekay/Documents/projects/django/deploy/techV2/techv2-venv/lib/python3.10/site-packages/django/contrib/auth/decorators.py", line 23, in _wrapper_view
    return view_func(request, *args, **kwargs)
  File "/home/peekay/Documents/projects/django/deploy/techV2/techv2-venv/lib/python3.10/site-packages/django/views/decorators/csrf.py", line 56, in wrapper_view
    return view_func(*args, **kwargs)
  File "/home/peekay/Documents/projects/django/deploy/techV2/investor/views.py", line 819, in init_stk
    description = response["ResponseDescription"],
KeyError: 'ResponseDescription'
/home/peekay/Documents/projects/django/deploy/techV2/investor/views.py changed, reloading.
Watching for file changes with StatReloader
/home/peekay/Documents/projects/django/deploy/techV2/investor/views.py changed, reloading.
Watching for file changes with StatReloader
Internal Server Error: /stkpush
Traceback (most recent call last):
  File "/home/peekay/Documents/projects/django/deploy/techV2/techv2-venv/lib/python3.10/site-packages/django/core/handlers/exception.py", line 55, in inner
    response = get_response(request)
  File "/home/peekay/Documents/projects/django/deploy/techV2/techv2-venv/lib/python3.10/site-packages/django/core/handlers/base.py", line 197, in _get_response
    response = wrapped_callback(request, *callback_args, **callback_kwargs)
  File "/home/peekay/Documents/projects/django/deploy/techV2/techv2-venv/lib/python3.10/site-packages/django/contrib/auth/decorators.py", line 23, in _wrapper_view
    return view_func(request, *args, **kwargs)
  File "/home/peekay/Documents/projects/django/deploy/techV2/techv2-venv/lib/python3.10/site-packages/django/views/decorators/csrf.py", line 56, in wrapper_view
    return view_func(*args, **kwargs)
  File "/home/peekay/Documents/projects/django/deploy/techV2/investor/views.py", line 815, in init_stk
    if response["ResponseCode"] == 0:
KeyError: 'ResponseCode'
Internal Server Error: /stkpush
Traceback (most recent call last):
  File "/home/peekay/Documents/projects/django/deploy/techV2/techv2-venv/lib/python3.10/site-packages/django/core/handlers/exception.py", line 55, in inner
    response = get_response(request)
  File "/home/peekay/Documents/projects/django/deploy/techV2/techv2-venv/lib/python3.10/site-packages/django/core/handlers/base.py", line 197, in _get_response
    response = wrapped_callback(request, *callback_args, **callback_kwargs)
  File "/home/peekay/Documents/projects/django/deploy/techV2/techv2-venv/lib/python3.10/site-packages/django/contrib/auth/decorators.py", line 23, in _wrapper_view
    return view_func(request, *args, **kwargs)
  File "/home/peekay/Documents/projects/django/deploy/techV2/techv2-venv/lib/python3.10/site-packages/django/views/decorators/csrf.py", line 56, in wrapper_view
    return view_func(*args, **kwargs)
  File "/home/peekay/Documents/projects/django/deploy/techV2/investor/views.py", line 815, in init_stk
    if response["ResponseCode"] == 0:
KeyError: 'ResponseCode'
/home/peekay/Documents/projects/django/deploy/techV2/investor/views.py changed, reloading.
Watching for file changes with StatReloader
Internal Server Error: /stkpush
Traceback (most recent call last):
  File "/home/peekay/Documents/projects/django/deploy/techV2/techv2-venv/lib/python3.10/site-packages/django/core/handlers/exception.py", line 55, in inner
    response = get_response(request)
  File "/home/peekay/Documents/projects/django/deploy/techV2/techv2-venv/lib/python3.10/site-packages/django/core/handlers/base.py", line 197, in _get_response
    response = wrapped_callback(request, *callback_args, **callback_kwargs)
  File "/home/peekay/Documents/projects/django/deploy/techV2/techv2-venv/lib/python3.10/site-packages/django/contrib/auth/decorators.py", line 23, in _wrapper_view
    return view_func(request, *args, **kwargs)
  File "/home/peekay/Documents/projects/django/deploy/techV2/techv2-venv/lib/python3.10/site-packages/django/views/decorators/csrf.py", line 56, in wrapper_view
    return view_func(*args, **kwargs)
  File "/home/peekay/Documents/projects/django/deploy/techV2/investor/views.py", line 815, in init_stk
    if response["ResultCode"] == 0:
KeyError: 'ResultCode'
/home/peekay/Documents/projects/django/deploy/techV2/investor/views.py changed, reloading.
Watching for file changes with StatReloader
/home/peekay/Documents/projects/django/deploy/techV2/investor/views.py changed, reloading.
Watching for file changes with StatReloader
/home/peekay/Documents/projects/django/deploy/techV2/investor/views.py changed, reloading.
Watching for file changes with StatReloader
Internal Server Error: /stkpush
Traceback (most recent call last):
  File "/home/peekay/Documents/projects/django/deploy/techV2/techv2-venv/lib/python3.10/site-packages/django/core/handlers/exception.py", line 55, in inner
    response = get_response(request)
  File "/home/peekay/Documents/projects/django/deploy/techV2/techv2-venv/lib/python3.10/site-packages/django/core/handlers/base.py", line 197, in _get_response
    response = wrapped_callback(request, *callback_args, **callback_kwargs)
  File "/home/peekay/Documents/projects/django/deploy/techV2/techv2-venv/lib/python3.10/site-packages/django/contrib/auth/decorators.py", line 23, in _wrapper_view
    return view_func(request, *args, **kwargs)
  File "/home/peekay/Documents/projects/django/deploy/techV2/techv2-venv/lib/python3.10/site-packages/django/views/decorators/csrf.py", line 56, in wrapper_view
    return view_func(*args, **kwargs)
  File "/home/peekay/Documents/projects/django/deploy/techV2/investor/views.py", line 815, in init_stk
    if response["ResultCode"]:
KeyError: 'ResultCode'
/home/peekay/Documents/projects/django/deploy/techV2/investor/views.py changed, reloading.
Watching for file changes with StatReloader
/home/peekay/Documents/projects/django/deploy/techV2/investor/views.py changed, reloading.
Watching for file changes with StatReloader
/home/peekay/Documents/projects/django/deploy/techV2/investor/views.py changed, reloading.
Watching for file changes with StatReloader
/home/peekay/Documents/projects/django/deploy/techV2/investor/views.py changed, reloading.
Watching for file changes with StatReloader
/home/peekay/Documents/projects/django/deploy/techV2/investor/views.py changed, reloading.
Watching for file changes with StatReloader
Internal Server Error: /stkpush
Traceback (most recent call last):
  File "/home/peekay/Documents/projects/django/deploy/techV2/investor/views.py", line 816, in init_stk
    if response["ResultCode"]:
KeyError: 'ResultCode'

During handling of the above exception, another exception occurred:

Traceback (most recent call last):
  File "/home/peekay/Documents/projects/django/deploy/techV2/techv2-venv/lib/python3.10/site-packages/django/core/handlers/exception.py", line 55, in inner
    response = get_response(request)
  File "/home/peekay/Documents/projects/django/deploy/techV2/techv2-venv/lib/python3.10/site-packages/django/core/handlers/base.py", line 197, in _get_response
    response = wrapped_callback(request, *callback_args, **callback_kwargs)
  File "/home/peekay/Documents/projects/django/deploy/techV2/techv2-venv/lib/python3.10/site-packages/django/contrib/auth/decorators.py", line 23, in _wrapper_view
    return view_func(request, *args, **kwargs)
  File "/home/peekay/Documents/projects/django/deploy/techV2/techv2-venv/lib/python3.10/site-packages/django/views/decorators/csrf.py", line 56, in wrapper_view
    return view_func(*args, **kwargs)
  File "/home/peekay/Documents/projects/django/deploy/techV2/investor/views.py", line 827, in init_stk
    if response["errorMessage"]:
KeyError: 'errorMessage'
/home/peekay/Documents/projects/django/deploy/techV2/investor/views.py changed, reloading.
Watching for file changes with StatReloader
Internal Server Error: /stkpush
Traceback (most recent call last):
  File "/home/peekay/Documents/projects/django/deploy/techV2/investor/views.py", line 816, in init_stk
    if response["ResultCode"]:
KeyError: 'ResultCode'

During handling of the above exception, another exception occurred:

Traceback (most recent call last):
  File "/home/peekay/Documents/projects/django/deploy/techV2/techv2-venv/lib/python3.10/site-packages/django/core/handlers/exception.py", line 55, in inner
    response = get_response(request)
  File "/home/peekay/Documents/projects/django/deploy/techV2/techv2-venv/lib/python3.10/site-packages/django/core/handlers/base.py", line 197, in _get_response
    response = wrapped_callback(request, *callback_args, **callback_kwargs)
  File "/home/peekay/Documents/projects/django/deploy/techV2/techv2-venv/lib/python3.10/site-packages/django/contrib/auth/decorators.py", line 23, in _wrapper_view
    return view_func(request, *args, **kwargs)
  File "/home/peekay/Documents/projects/django/deploy/techV2/techv2-venv/lib/python3.10/site-packages/django/views/decorators/csrf.py", line 56, in wrapper_view
    return view_func(*args, **kwargs)
  File "/home/peekay/Documents/projects/django/deploy/techV2/investor/views.py", line 826, in init_stk
    except response["errorMessage"]:
KeyError: 'errorMessage'
Internal Server Error: /stkpush
Traceback (most recent call last):
  File "/home/peekay/Documents/projects/django/deploy/techV2/investor/views.py", line 816, in init_stk
    if response["ResultCode"]:
KeyError: 'ResultCode'

During handling of the above exception, another exception occurred:

Traceback (most recent call last):
  File "/home/peekay/Documents/projects/django/deploy/techV2/techv2-venv/lib/python3.10/site-packages/django/core/handlers/exception.py", line 55, in inner
    response = get_response(request)
  File "/home/peekay/Documents/projects/django/deploy/techV2/techv2-venv/lib/python3.10/site-packages/django/core/handlers/base.py", line 197, in _get_response
    response = wrapped_callback(request, *callback_args, **callback_kwargs)
  File "/home/peekay/Documents/projects/django/deploy/techV2/techv2-venv/lib/python3.10/site-packages/django/contrib/auth/decorators.py", line 23, in _wrapper_view
    return view_func(request, *args, **kwargs)
  File "/home/peekay/Documents/projects/django/deploy/techV2/techv2-venv/lib/python3.10/site-packages/django/views/decorators/csrf.py", line 56, in wrapper_view
    return view_func(*args, **kwargs)
  File "/home/peekay/Documents/projects/django/deploy/techV2/investor/views.py", line 826, in init_stk
    except response["errorMessage"]:
KeyError: 'errorMessage'
/home/peekay/Documents/projects/django/deploy/techV2/investor/views.py changed, reloading.
Watching for file changes with StatReloader
Internal Server Error: /stkpush
Traceback (most recent call last):
  File "/home/peekay/Documents/projects/django/deploy/techV2/investor/views.py", line 816, in init_stk
    if response["ResultCode"]:
KeyError: 'ResultCode'

During handling of the above exception, another exception occurred:

Traceback (most recent call last):
  File "/home/peekay/Documents/projects/django/deploy/techV2/techv2-venv/lib/python3.10/site-packages/django/core/handlers/exception.py", line 55, in inner
    response = get_response(request)
  File "/home/peekay/Documents/projects/django/deploy/techV2/techv2-venv/lib/python3.10/site-packages/django/core/handlers/base.py", line 197, in _get_response
    response = wrapped_callback(request, *callback_args, **callback_kwargs)
  File "/home/peekay/Documents/projects/django/deploy/techV2/techv2-venv/lib/python3.10/site-packages/django/contrib/auth/decorators.py", line 23, in _wrapper_view
    return view_func(request, *args, **kwargs)
  File "/home/peekay/Documents/projects/django/deploy/techV2/techv2-venv/lib/python3.10/site-packages/django/views/decorators/csrf.py", line 56, in wrapper_view
    return view_func(*args, **kwargs)
  File "/home/peekay/Documents/projects/django/deploy/techV2/investor/views.py", line 826, in init_stk
    except response == response["errorMessage"]:
KeyError: 'errorMessage'
/home/peekay/Documents/projects/django/deploy/techV2/investor/views.py changed, reloading.
Watching for file changes with StatReloader
Internal Server Error: /stkpush
Traceback (most recent call last):
  File "/home/peekay/Documents/projects/django/deploy/techV2/investor/views.py", line 816, in init_stk
    if response["ResultCode"]:
KeyError: 'ResultCode'

During handling of the above exception, another exception occurred:

Traceback (most recent call last):
  File "/home/peekay/Documents/projects/django/deploy/techV2/techv2-venv/lib/python3.10/site-packages/django/core/handlers/exception.py", line 55, in inner
    response = get_response(request)
  File "/home/peekay/Documents/projects/django/deploy/techV2/techv2-venv/lib/python3.10/site-packages/django/core/handlers/base.py", line 197, in _get_response
    response = wrapped_callback(request, *callback_args, **callback_kwargs)
  File "/home/peekay/Documents/projects/django/deploy/techV2/techv2-venv/lib/python3.10/site-packages/django/contrib/auth/decorators.py", line 23, in _wrapper_view
    return view_func(request, *args, **kwargs)
  File "/home/peekay/Documents/projects/django/deploy/techV2/techv2-venv/lib/python3.10/site-packages/django/views/decorators/csrf.py", line 56, in wrapper_view
    return view_func(*args, **kwargs)
  File "/home/peekay/Documents/projects/django/deploy/techV2/investor/views.py", line 827, in init_stk
    print(response["errorMessage"])
KeyError: 'errorMessage'
/home/peekay/Documents/projects/django/deploy/techV2/investor/views.py changed, reloading.
Watching for file changes with StatReloader
Internal Server Error: /stkpush
Traceback (most recent call last):
  File "/home/peekay/Documents/projects/django/deploy/techV2/investor/views.py", line 815, in init_stk
    if response["ResultCode"]:
KeyError: 'ResultCode'

During handling of the above exception, another exception occurred:

Traceback (most recent call last):
  File "/home/peekay/Documents/projects/django/deploy/techV2/techv2-venv/lib/python3.10/site-packages/django/core/handlers/exception.py", line 55, in inner
    response = get_response(request)
  File "/home/peekay/Documents/projects/django/deploy/techV2/techv2-venv/lib/python3.10/site-packages/django/core/handlers/base.py", line 197, in _get_response
    response = wrapped_callback(request, *callback_args, **callback_kwargs)
  File "/home/peekay/Documents/projects/django/deploy/techV2/techv2-venv/lib/python3.10/site-packages/django/contrib/auth/decorators.py", line 23, in _wrapper_view
    return view_func(request, *args, **kwargs)
  File "/home/peekay/Documents/projects/django/deploy/techV2/techv2-venv/lib/python3.10/site-packages/django/views/decorators/csrf.py", line 56, in wrapper_view
    return view_func(*args, **kwargs)
  File "/home/peekay/Documents/projects/django/deploy/techV2/investor/views.py", line 826, in init_stk
    print(response["errorMessage"])
KeyError: 'errorMessage'
/home/peekay/Documents/projects/django/deploy/techV2/investor/views.py changed, reloading.
Watching for file changes with StatReloader
/home/peekay/Documents/projects/django/deploy/techV2/investor/views.py changed, reloading.
Watching for file changes with StatReloader
/home/peekay/Documents/projects/django/deploy/techV2/investor/views.py changed, reloading.
Watching for file changes with StatReloader
/home/peekay/Documents/projects/django/deploy/techV2/investor/views.py changed, reloading.
Watching for file changes with StatReloader
/home/peekay/Documents/projects/django/deploy/techV2/investor/views.py changed, reloading.
Watching for file changes with StatReloader
/home/peekay/Documents/projects/django/deploy/techV2/investor/models.py changed, reloading.
Watching for file changes with StatReloader
Internal Server Error: /stkpush
Traceback (most recent call last):
  File "/home/peekay/Documents/projects/django/deploy/techV2/techv2-venv/lib/python3.10/site-packages/django/db/backends/utils.py", line 89, in _execute
    return self.cursor.execute(sql, params)
psycopg2.errors.UndefinedColumn: column "user_id" of relation "investor_mpesarequest" does not exist
LINE 1: INSERT INTO "investor_mpesarequest" ("user_id", "amount", "p...
                                             ^


The above exception was the direct cause of the following exception:

Traceback (most recent call last):
  File "/home/peekay/Documents/projects/django/deploy/techV2/investor/views.py", line 810, in init_stk
    MpesaRequest.objects.create(
  File "/home/peekay/Documents/projects/django/deploy/techV2/techv2-venv/lib/python3.10/site-packages/django/db/models/manager.py", line 87, in manager_method
    return getattr(self.get_queryset(), name)(*args, **kwargs)
  File "/home/peekay/Documents/projects/django/deploy/techV2/techv2-venv/lib/python3.10/site-packages/django/db/models/query.py", line 658, in create
    obj.save(force_insert=True, using=self.db)
  File "/home/peekay/Documents/projects/django/deploy/techV2/techv2-venv/lib/python3.10/site-packages/django/db/models/base.py", line 814, in save
    self.save_base(
  File "/home/peekay/Documents/projects/django/deploy/techV2/techv2-venv/lib/python3.10/site-packages/django/db/models/base.py", line 877, in save_base
    updated = self._save_table(
  File "/home/peekay/Documents/projects/django/deploy/techV2/techv2-venv/lib/python3.10/site-packages/django/db/models/base.py", line 1020, in _save_table
    results = self._do_insert(
  File "/home/peekay/Documents/projects/django/deploy/techV2/techv2-venv/lib/python3.10/site-packages/django/db/models/base.py", line 1061, in _do_insert
    return manager._insert(
  File "/home/peekay/Documents/projects/django/deploy/techV2/techv2-venv/lib/python3.10/site-packages/django/db/models/manager.py", line 87, in manager_method
    return getattr(self.get_queryset(), name)(*args, **kwargs)
  File "/home/peekay/Documents/projects/django/deploy/techV2/techv2-venv/lib/python3.10/site-packages/django/db/models/query.py", line 1805, in _insert
    return query.get_compiler(using=using).execute_sql(returning_fields)
  File "/home/peekay/Documents/projects/django/deploy/techV2/techv2-venv/lib/python3.10/site-packages/django/db/models/sql/compiler.py", line 1822, in execute_sql
    cursor.execute(sql, params)
  File "/home/peekay/Documents/projects/django/deploy/techV2/techv2-venv/lib/python3.10/site-packages/django/db/backends/utils.py", line 102, in execute
    return super().execute(sql, params)
  File "/home/peekay/Documents/projects/django/deploy/techV2/techv2-venv/lib/python3.10/site-packages/django/db/backends/utils.py", line 67, in execute
    return self._execute_with_wrappers(
  File "/home/peekay/Documents/projects/django/deploy/techV2/techv2-venv/lib/python3.10/site-packages/django/db/backends/utils.py", line 80, in _execute_with_wrappers
    return executor(sql, params, many, context)
  File "/home/peekay/Documents/projects/django/deploy/techV2/techv2-venv/lib/python3.10/site-packages/django/db/backends/utils.py", line 84, in _execute
    with self.db.wrap_database_errors:
  File "/home/peekay/Documents/projects/django/deploy/techV2/techv2-venv/lib/python3.10/site-packages/django/db/utils.py", line 91, in __exit__
    raise dj_exc_value.with_traceback(traceback) from exc_value
  File "/home/peekay/Documents/projects/django/deploy/techV2/techv2-venv/lib/python3.10/site-packages/django/db/backends/utils.py", line 89, in _execute
    return self.cursor.execute(sql, params)
django.db.utils.ProgrammingError: column "user_id" of relation "investor_mpesarequest" does not exist
LINE 1: INSERT INTO "investor_mpesarequest" ("user_id", "amount", "p...
                                             ^


During handling of the above exception, another exception occurred:

Traceback (most recent call last):
  File "/home/peekay/Documents/projects/django/deploy/techV2/techv2-venv/lib/python3.10/site-packages/django/db/backends/utils.py", line 89, in _execute
    return self.cursor.execute(sql, params)
psycopg2.errors.UndefinedColumn: column "user_id" of relation "investor_mpesarequest" does not exist
LINE 1: INSERT INTO "investor_mpesarequest" ("user_id", "amount", "p...
                                             ^


The above exception was the direct cause of the following exception:

Traceback (most recent call last):
  File "/home/peekay/Documents/projects/django/deploy/techV2/techv2-venv/lib/python3.10/site-packages/django/core/handlers/exception.py", line 55, in inner
    response = get_response(request)
  File "/home/peekay/Documents/projects/django/deploy/techV2/techv2-venv/lib/python3.10/site-packages/django/core/handlers/base.py", line 197, in _get_response
    response = wrapped_callback(request, *callback_args, **callback_kwargs)
  File "/home/peekay/Documents/projects/django/deploy/techV2/techv2-venv/lib/python3.10/site-packages/django/contrib/auth/decorators.py", line 23, in _wrapper_view
    return view_func(request, *args, **kwargs)
  File "/home/peekay/Documents/projects/django/deploy/techV2/techv2-venv/lib/python3.10/site-packages/django/views/decorators/csrf.py", line 56, in wrapper_view
    return view_func(*args, **kwargs)
  File "/home/peekay/Documents/projects/django/deploy/techV2/investor/views.py", line 833, in init_stk
    MpesaRequest.objects.create(
  File "/home/peekay/Documents/projects/django/deploy/techV2/techv2-venv/lib/python3.10/site-packages/django/db/models/manager.py", line 87, in manager_method
    return getattr(self.get_queryset(), name)(*args, **kwargs)
  File "/home/peekay/Documents/projects/django/deploy/techV2/techv2-venv/lib/python3.10/site-packages/django/db/models/query.py", line 658, in create
    obj.save(force_insert=True, using=self.db)
  File "/home/peekay/Documents/projects/django/deploy/techV2/techv2-venv/lib/python3.10/site-packages/django/db/models/base.py", line 814, in save
    self.save_base(
  File "/home/peekay/Documents/projects/django/deploy/techV2/techv2-venv/lib/python3.10/site-packages/django/db/models/base.py", line 877, in save_base
    updated = self._save_table(
  File "/home/peekay/Documents/projects/django/deploy/techV2/techv2-venv/lib/python3.10/site-packages/django/db/models/base.py", line 1020, in _save_table
    results = self._do_insert(
  File "/home/peekay/Documents/projects/django/deploy/techV2/techv2-venv/lib/python3.10/site-packages/django/db/models/base.py", line 1061, in _do_insert
    return manager._insert(
  File "/home/peekay/Documents/projects/django/deploy/techV2/techv2-venv/lib/python3.10/site-packages/django/db/models/manager.py", line 87, in manager_method
    return getattr(self.get_queryset(), name)(*args, **kwargs)
  File "/home/peekay/Documents/projects/django/deploy/techV2/techv2-venv/lib/python3.10/site-packages/django/db/models/query.py", line 1805, in _insert
    return query.get_compiler(using=using).execute_sql(returning_fields)
  File "/home/peekay/Documents/projects/django/deploy/techV2/techv2-venv/lib/python3.10/site-packages/django/db/models/sql/compiler.py", line 1822, in execute_sql
    cursor.execute(sql, params)
  File "/home/peekay/Documents/projects/django/deploy/techV2/techv2-venv/lib/python3.10/site-packages/django/db/backends/utils.py", line 102, in execute
    return super().execute(sql, params)
  File "/home/peekay/Documents/projects/django/deploy/techV2/techv2-venv/lib/python3.10/site-packages/django/db/backends/utils.py", line 67, in execute
    return self._execute_with_wrappers(
  File "/home/peekay/Documents/projects/django/deploy/techV2/techv2-venv/lib/python3.10/site-packages/django/db/backends/utils.py", line 80, in _execute_with_wrappers
    return executor(sql, params, many, context)
  File "/home/peekay/Documents/projects/django/deploy/techV2/techv2-venv/lib/python3.10/site-packages/django/db/backends/utils.py", line 84, in _execute
    with self.db.wrap_database_errors:
  File "/home/peekay/Documents/projects/django/deploy/techV2/techv2-venv/lib/python3.10/site-packages/django/db/utils.py", line 91, in __exit__
    raise dj_exc_value.with_traceback(traceback) from exc_value
  File "/home/peekay/Documents/projects/django/deploy/techV2/techv2-venv/lib/python3.10/site-packages/django/db/backends/utils.py", line 89, in _execute
    return self.cursor.execute(sql, params)
django.db.utils.ProgrammingError: column "user_id" of relation "investor_mpesarequest" does not exist
LINE 1: INSERT INTO "investor_mpesarequest" ("user_id", "amount", "p...
                                             ^

Watching for file changes with StatReloader
Not Found: /favicon.ico
Internal Server Error: /stkpush
Traceback (most recent call last):
  File "/home/peekay/Documents/projects/django/deploy/techV2/techv2-venv/lib/python3.10/site-packages/urllib3/connectionpool.py", line 793, in urlopen
    response = self._make_request(
  File "/home/peekay/Documents/projects/django/deploy/techV2/techv2-venv/lib/python3.10/site-packages/urllib3/connectionpool.py", line 537, in _make_request
    response = conn.getresponse()
  File "/home/peekay/Documents/projects/django/deploy/techV2/techv2-venv/lib/python3.10/site-packages/urllib3/connection.py", line 466, in getresponse
    httplib_response = super().getresponse()
  File "/usr/lib/python3.10/http/client.py", line 1375, in getresponse
    response.begin()
  File "/usr/lib/python3.10/http/client.py", line 318, in begin
    version, status, reason = self._read_status()
  File "/usr/lib/python3.10/http/client.py", line 287, in _read_status
    raise RemoteDisconnected("Remote end closed connection without"
http.client.RemoteDisconnected: Remote end closed connection without response

During handling of the above exception, another exception occurred:

Traceback (most recent call last):
  File "/home/peekay/Documents/projects/django/deploy/techV2/techv2-venv/lib/python3.10/site-packages/requests/adapters.py", line 667, in send
    resp = conn.urlopen(
  File "/home/peekay/Documents/projects/django/deploy/techV2/techv2-venv/lib/python3.10/site-packages/urllib3/connectionpool.py", line 847, in urlopen
    retries = retries.increment(
  File "/home/peekay/Documents/projects/django/deploy/techV2/techv2-venv/lib/python3.10/site-packages/urllib3/util/retry.py", line 470, in increment
    raise reraise(type(error), error, _stacktrace)
  File "/home/peekay/Documents/projects/django/deploy/techV2/techv2-venv/lib/python3.10/site-packages/urllib3/util/util.py", line 38, in reraise
    raise value.with_traceback(tb)
  File "/home/peekay/Documents/projects/django/deploy/techV2/techv2-venv/lib/python3.10/site-packages/urllib3/connectionpool.py", line 793, in urlopen
    response = self._make_request(
  File "/home/peekay/Documents/projects/django/deploy/techV2/techv2-venv/lib/python3.10/site-packages/urllib3/connectionpool.py", line 537, in _make_request
    response = conn.getresponse()
  File "/home/peekay/Documents/projects/django/deploy/techV2/techv2-venv/lib/python3.10/site-packages/urllib3/connection.py", line 466, in getresponse
    httplib_response = super().getresponse()
  File "/usr/lib/python3.10/http/client.py", line 1375, in getresponse
    response.begin()
  File "/usr/lib/python3.10/http/client.py", line 318, in begin
    version, status, reason = self._read_status()
  File "/usr/lib/python3.10/http/client.py", line 287, in _read_status
    raise RemoteDisconnected("Remote end closed connection without"
urllib3.exceptions.ProtocolError: ('Connection aborted.', RemoteDisconnected('Remote end closed connection without response'))

During handling of the above exception, another exception occurred:

Traceback (most recent call last):
  File "/home/peekay/Documents/projects/django/deploy/techV2/techv2-venv/lib/python3.10/site-packages/django/core/handlers/exception.py", line 55, in inner
    response = get_response(request)
  File "/home/peekay/Documents/projects/django/deploy/techV2/techv2-venv/lib/python3.10/site-packages/django/core/handlers/base.py", line 197, in _get_response
    response = wrapped_callback(request, *callback_args, **callback_kwargs)
  File "/home/peekay/Documents/projects/django/deploy/techV2/techv2-venv/lib/python3.10/site-packages/django/contrib/auth/decorators.py", line 23, in _wrapper_view
    return view_func(request, *args, **kwargs)
  File "/home/peekay/Documents/projects/django/deploy/techV2/techv2-venv/lib/python3.10/site-packages/django/views/decorators/csrf.py", line 56, in wrapper_view
    return view_func(*args, **kwargs)
  File "/home/peekay/Documents/projects/django/deploy/techV2/investor/views.py", line 783, in init_stk
    access_token = get_access_token()
  File "/home/peekay/Documents/projects/django/deploy/techV2/investor/views.py", line 749, in get_access_token
    r = requests.get(endpoint, auth=HTTPBasicAuth(consumer_key, consumer_secret))
  File "/home/peekay/Documents/projects/django/deploy/techV2/techv2-venv/lib/python3.10/site-packages/requests/api.py", line 73, in get
    return request("get", url, params=params, **kwargs)
  File "/home/peekay/Documents/projects/django/deploy/techV2/techv2-venv/lib/python3.10/site-packages/requests/api.py", line 59, in request
    return session.request(method=method, url=url, **kwargs)
  File "/home/peekay/Documents/projects/django/deploy/techV2/techv2-venv/lib/python3.10/site-packages/requests/sessions.py", line 589, in request
    resp = self.send(prep, **send_kwargs)
  File "/home/peekay/Documents/projects/django/deploy/techV2/techv2-venv/lib/python3.10/site-packages/requests/sessions.py", line 703, in send
    r = adapter.send(request, **kwargs)
  File "/home/peekay/Documents/projects/django/deploy/techV2/techv2-venv/lib/python3.10/site-packages/requests/adapters.py", line 682, in send
    raise ConnectionError(err, request=request)
requests.exceptions.ConnectionError: ('Connection aborted.', RemoteDisconnected('Remote end closed connection without response'))
Watching for file changes with StatReloader
Internal Server Error: /stkpush
Traceback (most recent call last):
  File "/home/peekay/Documents/projects/django/deploy/techV2/techv2-venv/lib/python3.10/site-packages/urllib3/connectionpool.py", line 793, in urlopen
    response = self._make_request(
  File "/home/peekay/Documents/projects/django/deploy/techV2/techv2-venv/lib/python3.10/site-packages/urllib3/connectionpool.py", line 537, in _make_request
    response = conn.getresponse()
  File "/home/peekay/Documents/projects/django/deploy/techV2/techv2-venv/lib/python3.10/site-packages/urllib3/connection.py", line 466, in getresponse
    httplib_response = super().getresponse()
  File "/usr/lib/python3.10/http/client.py", line 1375, in getresponse
    response.begin()
  File "/usr/lib/python3.10/http/client.py", line 318, in begin
    version, status, reason = self._read_status()
  File "/usr/lib/python3.10/http/client.py", line 287, in _read_status
    raise RemoteDisconnected("Remote end closed connection without"
http.client.RemoteDisconnected: Remote end closed connection without response

During handling of the above exception, another exception occurred:

Traceback (most recent call last):
  File "/home/peekay/Documents/projects/django/deploy/techV2/techv2-venv/lib/python3.10/site-packages/requests/adapters.py", line 667, in send
    resp = conn.urlopen(
  File "/home/peekay/Documents/projects/django/deploy/techV2/techv2-venv/lib/python3.10/site-packages/urllib3/connectionpool.py", line 847, in urlopen
    retries = retries.increment(
  File "/home/peekay/Documents/projects/django/deploy/techV2/techv2-venv/lib/python3.10/site-packages/urllib3/util/retry.py", line 470, in increment
    raise reraise(type(error), error, _stacktrace)
  File "/home/peekay/Documents/projects/django/deploy/techV2/techv2-venv/lib/python3.10/site-packages/urllib3/util/util.py", line 38, in reraise
    raise value.with_traceback(tb)
  File "/home/peekay/Documents/projects/django/deploy/techV2/techv2-venv/lib/python3.10/site-packages/urllib3/connectionpool.py", line 793, in urlopen
    response = self._make_request(
  File "/home/peekay/Documents/projects/django/deploy/techV2/techv2-venv/lib/python3.10/site-packages/urllib3/connectionpool.py", line 537, in _make_request
    response = conn.getresponse()
  File "/home/peekay/Documents/projects/django/deploy/techV2/techv2-venv/lib/python3.10/site-packages/urllib3/connection.py", line 466, in getresponse
    httplib_response = super().getresponse()
  File "/usr/lib/python3.10/http/client.py", line 1375, in getresponse
    response.begin()
  File "/usr/lib/python3.10/http/client.py", line 318, in begin
    version, status, reason = self._read_status()
  File "/usr/lib/python3.10/http/client.py", line 287, in _read_status
    raise RemoteDisconnected("Remote end closed connection without"
urllib3.exceptions.ProtocolError: ('Connection aborted.', RemoteDisconnected('Remote end closed connection without response'))

During handling of the above exception, another exception occurred:

Traceback (most recent call last):
  File "/home/peekay/Documents/projects/django/deploy/techV2/techv2-venv/lib/python3.10/site-packages/django/core/handlers/exception.py", line 55, in inner
    response = get_response(request)
  File "/home/peekay/Documents/projects/django/deploy/techV2/techv2-venv/lib/python3.10/site-packages/django/core/handlers/base.py", line 197, in _get_response
    response = wrapped_callback(request, *callback_args, **callback_kwargs)
  File "/home/peekay/Documents/projects/django/deploy/techV2/techv2-venv/lib/python3.10/site-packages/django/contrib/auth/decorators.py", line 23, in _wrapper_view
    return view_func(request, *args, **kwargs)
  File "/home/peekay/Documents/projects/django/deploy/techV2/techv2-venv/lib/python3.10/site-packages/django/views/decorators/csrf.py", line 56, in wrapper_view
    return view_func(*args, **kwargs)
  File "/home/peekay/Documents/projects/django/deploy/techV2/investor/views.py", line 783, in init_stk
    access_token = get_access_token()
  File "/home/peekay/Documents/projects/django/deploy/techV2/investor/views.py", line 749, in get_access_token
    r = requests.get(endpoint, auth=HTTPBasicAuth(consumer_key, consumer_secret))
  File "/home/peekay/Documents/projects/django/deploy/techV2/techv2-venv/lib/python3.10/site-packages/requests/api.py", line 73, in get
    return request("get", url, params=params, **kwargs)
  File "/home/peekay/Documents/projects/django/deploy/techV2/techv2-venv/lib/python3.10/site-packages/requests/api.py", line 59, in request
    return session.request(method=method, url=url, **kwargs)
  File "/home/peekay/Documents/projects/django/deploy/techV2/techv2-venv/lib/python3.10/site-packages/requests/sessions.py", line 589, in request
    resp = self.send(prep, **send_kwargs)
  File "/home/peekay/Documents/projects/django/deploy/techV2/techv2-venv/lib/python3.10/site-packages/requests/sessions.py", line 703, in send
    r = adapter.send(request, **kwargs)
  File "/home/peekay/Documents/projects/django/deploy/techV2/techv2-venv/lib/python3.10/site-packages/requests/adapters.py", line 682, in send
    raise ConnectionError(err, request=request)
requests.exceptions.ConnectionError: ('Connection aborted.', RemoteDisconnected('Remote end closed connection without response'))
Watching for file changes with StatReloader
Internal Server Error: /stkpush
Traceback (most recent call last):
  File "/home/peekay/Documents/projects/django/deploy/techV2/techv2-venv/lib/python3.10/site-packages/django/core/handlers/exception.py", line 55, in inner
    response = get_response(request)
  File "/home/peekay/Documents/projects/django/deploy/techV2/techv2-venv/lib/python3.10/site-packages/django/core/handlers/base.py", line 197, in _get_response
    response = wrapped_callback(request, *callback_args, **callback_kwargs)
  File "/home/peekay/Documents/projects/django/deploy/techV2/techv2-venv/lib/python3.10/site-packages/django/contrib/auth/decorators.py", line 23, in _wrapper_view
    return view_func(request, *args, **kwargs)
  File "/home/peekay/Documents/projects/django/deploy/techV2/techv2-venv/lib/python3.10/site-packages/django/views/decorators/csrf.py", line 56, in wrapper_view
    return view_func(*args, **kwargs)
  File "/home/peekay/Documents/projects/django/deploy/techV2/investor/views.py", line 840, in init_stk
    context = {"response": response}
UnboundLocalError: local variable 'response' referenced before assignment
/home/peekay/Documents/projects/django/deploy/techV2/investor/views.py changed, reloading.
Watching for file changes with StatReloader
Internal Server Error: /stkpush
Traceback (most recent call last):
  File "/home/peekay/Documents/projects/django/deploy/techV2/techv2-venv/lib/python3.10/site-packages/django/core/handlers/exception.py", line 55, in inner
    response = get_response(request)
  File "/home/peekay/Documents/projects/django/deploy/techV2/techv2-venv/lib/python3.10/site-packages/django/core/handlers/base.py", line 197, in _get_response
    response = wrapped_callback(request, *callback_args, **callback_kwargs)
  File "/home/peekay/Documents/projects/django/deploy/techV2/techv2-venv/lib/python3.10/site-packages/django/contrib/auth/decorators.py", line 23, in _wrapper_view
    return view_func(request, *args, **kwargs)
  File "/home/peekay/Documents/projects/django/deploy/techV2/techv2-venv/lib/python3.10/site-packages/django/views/decorators/csrf.py", line 56, in wrapper_view
    return view_func(*args, **kwargs)
  File "/home/peekay/Documents/projects/django/deploy/techV2/investor/views.py", line 803, in init_stk
    reponse = res.json()
UnboundLocalError: local variable 'res' referenced before assignment
/home/peekay/Documents/projects/django/deploy/techV2/investor/views.py changed, reloading.
Watching for file changes with StatReloader
Not Found: /favicon.ico
Not Found: /admin
/home/peekay/Documents/projects/django/deploy/techV2/investor/views.py changed, reloading.
Watching for file changes with StatReloader
Internal Server Error: /stkpush
Traceback (most recent call last):
  File "/home/peekay/Documents/projects/django/deploy/techV2/techv2-venv/lib/python3.10/site-packages/django/core/handlers/exception.py", line 55, in inner
    response = get_response(request)
  File "/home/peekay/Documents/projects/django/deploy/techV2/techv2-venv/lib/python3.10/site-packages/django/core/handlers/base.py", line 197, in _get_response
    response = wrapped_callback(request, *callback_args, **callback_kwargs)
  File "/home/peekay/Documents/projects/django/deploy/techV2/techv2-venv/lib/python3.10/site-packages/django/contrib/auth/decorators.py", line 23, in _wrapper_view
    return view_func(request, *args, **kwargs)
  File "/home/peekay/Documents/projects/django/deploy/techV2/techv2-venv/lib/python3.10/site-packages/django/views/decorators/csrf.py", line 56, in wrapper_view
    return view_func(*args, **kwargs)
  File "/home/peekay/Documents/projects/django/deploy/techV2/investor/views.py", line 783, in init_stk
    access_token = get_access_token()
  File "/home/peekay/Documents/projects/django/deploy/techV2/investor/views.py", line 750, in get_access_token
    data = json.loads(r.text)
  File "/usr/lib/python3.10/json/__init__.py", line 346, in loads
    return _default_decoder.decode(s)
  File "/usr/lib/python3.10/json/decoder.py", line 337, in decode
    obj, end = self.raw_decode(s, idx=_w(s, 0).end())
  File "/usr/lib/python3.10/json/decoder.py", line 355, in raw_decode
    raise JSONDecodeError("Expecting value", s, err.value) from None
json.decoder.JSONDecodeError: Expecting value: line 1 column 1 (char 0)
Not Found: /favicon.ico
Internal Server Error: /stkpush
Traceback (most recent call last):
  File "/home/peekay/Documents/projects/django/deploy/techV2/techv2-venv/lib/python3.10/site-packages/urllib3/connection.py", line 198, in _new_conn
    sock = connection.create_connection(
  File "/home/peekay/Documents/projects/django/deploy/techV2/techv2-venv/lib/python3.10/site-packages/urllib3/util/connection.py", line 60, in create_connection
    for res in socket.getaddrinfo(host, port, family, socket.SOCK_STREAM):
  File "/usr/lib/python3.10/socket.py", line 955, in getaddrinfo
    for res in _socket.getaddrinfo(host, port, family, type, proto, flags):
socket.gaierror: [Errno -5] No address associated with hostname

The above exception was the direct cause of the following exception:

Traceback (most recent call last):
  File "/home/peekay/Documents/projects/django/deploy/techV2/techv2-venv/lib/python3.10/site-packages/urllib3/connectionpool.py", line 793, in urlopen
    response = self._make_request(
  File "/home/peekay/Documents/projects/django/deploy/techV2/techv2-venv/lib/python3.10/site-packages/urllib3/connectionpool.py", line 491, in _make_request
    raise new_e
  File "/home/peekay/Documents/projects/django/deploy/techV2/techv2-venv/lib/python3.10/site-packages/urllib3/connectionpool.py", line 467, in _make_request
    self._validate_conn(conn)
  File "/home/peekay/Documents/projects/django/deploy/techV2/techv2-venv/lib/python3.10/site-packages/urllib3/connectionpool.py", line 1099, in _validate_conn
    conn.connect()
  File "/home/peekay/Documents/projects/django/deploy/techV2/techv2-venv/lib/python3.10/site-packages/urllib3/connection.py", line 616, in connect
    self.sock = sock = self._new_conn()
  File "/home/peekay/Documents/projects/django/deploy/techV2/techv2-venv/lib/python3.10/site-packages/urllib3/connection.py", line 205, in _new_conn
    raise NameResolutionError(self.host, self, e) from e
urllib3.exceptions.NameResolutionError: <urllib3.connection.HTTPSConnection object at 0x779af4206f20>: Failed to resolve 'sandbox.safaricom.co.ke' ([Errno -5] No address associated with hostname)

The above exception was the direct cause of the following exception:

Traceback (most recent call last):
  File "/home/peekay/Documents/projects/django/deploy/techV2/techv2-venv/lib/python3.10/site-packages/requests/adapters.py", line 667, in send
    resp = conn.urlopen(
  File "/home/peekay/Documents/projects/django/deploy/techV2/techv2-venv/lib/python3.10/site-packages/urllib3/connectionpool.py", line 847, in urlopen
    retries = retries.increment(
  File "/home/peekay/Documents/projects/django/deploy/techV2/techv2-venv/lib/python3.10/site-packages/urllib3/util/retry.py", line 515, in increment
    raise MaxRetryError(_pool, url, reason) from reason  # type: ignore[arg-type]
urllib3.exceptions.MaxRetryError: HTTPSConnectionPool(host='sandbox.safaricom.co.ke', port=443): Max retries exceeded with url: /oauth/v1/generate?grant_type=client_credentials (Caused by NameResolutionError("<urllib3.connection.HTTPSConnection object at 0x779af4206f20>: Failed to resolve 'sandbox.safaricom.co.ke' ([Errno -5] No address associated with hostname)"))

During handling of the above exception, another exception occurred:

Traceback (most recent call last):
  File "/home/peekay/Documents/projects/django/deploy/techV2/techv2-venv/lib/python3.10/site-packages/django/core/handlers/exception.py", line 55, in inner
    response = get_response(request)
  File "/home/peekay/Documents/projects/django/deploy/techV2/techv2-venv/lib/python3.10/site-packages/django/core/handlers/base.py", line 197, in _get_response
    response = wrapped_callback(request, *callback_args, **callback_kwargs)
  File "/home/peekay/Documents/projects/django/deploy/techV2/techv2-venv/lib/python3.10/site-packages/django/contrib/auth/decorators.py", line 23, in _wrapper_view
    return view_func(request, *args, **kwargs)
  File "/home/peekay/Documents/projects/django/deploy/techV2/techv2-venv/lib/python3.10/site-packages/django/views/decorators/csrf.py", line 56, in wrapper_view
    return view_func(*args, **kwargs)
  File "/home/peekay/Documents/projects/django/deploy/techV2/investor/views.py", line 783, in init_stk
    access_token = get_access_token()
  File "/home/peekay/Documents/projects/django/deploy/techV2/investor/views.py", line 749, in get_access_token
    r = requests.get(endpoint, auth=HTTPBasicAuth(consumer_key, consumer_secret))
  File "/home/peekay/Documents/projects/django/deploy/techV2/techv2-venv/lib/python3.10/site-packages/requests/api.py", line 73, in get
    return request("get", url, params=params, **kwargs)
  File "/home/peekay/Documents/projects/django/deploy/techV2/techv2-venv/lib/python3.10/site-packages/requests/api.py", line 59, in request
    return session.request(method=method, url=url, **kwargs)
  File "/home/peekay/Documents/projects/django/deploy/techV2/techv2-venv/lib/python3.10/site-packages/requests/sessions.py", line 589, in request
    resp = self.send(prep, **send_kwargs)
  File "/home/peekay/Documents/projects/django/deploy/techV2/techv2-venv/lib/python3.10/site-packages/requests/sessions.py", line 703, in send
    r = adapter.send(request, **kwargs)
  File "/home/peekay/Documents/projects/django/deploy/techV2/techv2-venv/lib/python3.10/site-packages/requests/adapters.py", line 700, in send
    raise ConnectionError(e, request=request)
requests.exceptions.ConnectionError: HTTPSConnectionPool(host='sandbox.safaricom.co.ke', port=443): Max retries exceeded with url: /oauth/v1/generate?grant_type=client_credentials (Caused by NameResolutionError("<urllib3.connection.HTTPSConnection object at 0x779af4206f20>: Failed to resolve 'sandbox.safaricom.co.ke' ([Errno -5] No address associated with hostname)"))
Watching for file changes with StatReloader
Internal Server Error: /stkpush
Traceback (most recent call last):
  File "/home/peekay/Documents/projects/django/deploy/techV2/techv2-venv/lib/python3.10/site-packages/urllib3/connection.py", line 198, in _new_conn
    sock = connection.create_connection(
  File "/home/peekay/Documents/projects/django/deploy/techV2/techv2-venv/lib/python3.10/site-packages/urllib3/util/connection.py", line 60, in create_connection
    for res in socket.getaddrinfo(host, port, family, socket.SOCK_STREAM):
  File "/usr/lib/python3.10/socket.py", line 955, in getaddrinfo
    for res in _socket.getaddrinfo(host, port, family, type, proto, flags):
socket.gaierror: [Errno -5] No address associated with hostname

The above exception was the direct cause of the following exception:

Traceback (most recent call last):
  File "/home/peekay/Documents/projects/django/deploy/techV2/techv2-venv/lib/python3.10/site-packages/urllib3/connectionpool.py", line 793, in urlopen
    response = self._make_request(
  File "/home/peekay/Documents/projects/django/deploy/techV2/techv2-venv/lib/python3.10/site-packages/urllib3/connectionpool.py", line 491, in _make_request
    raise new_e
  File "/home/peekay/Documents/projects/django/deploy/techV2/techv2-venv/lib/python3.10/site-packages/urllib3/connectionpool.py", line 467, in _make_request
    self._validate_conn(conn)
  File "/home/peekay/Documents/projects/django/deploy/techV2/techv2-venv/lib/python3.10/site-packages/urllib3/connectionpool.py", line 1099, in _validate_conn
    conn.connect()
  File "/home/peekay/Documents/projects/django/deploy/techV2/techv2-venv/lib/python3.10/site-packages/urllib3/connection.py", line 616, in connect
    self.sock = sock = self._new_conn()
  File "/home/peekay/Documents/projects/django/deploy/techV2/techv2-venv/lib/python3.10/site-packages/urllib3/connection.py", line 205, in _new_conn
    raise NameResolutionError(self.host, self, e) from e
urllib3.exceptions.NameResolutionError: <urllib3.connection.HTTPSConnection object at 0x7a553d524a30>: Failed to resolve 'sandbox.safaricom.co.ke' ([Errno -5] No address associated with hostname)

The above exception was the direct cause of the following exception:

Traceback (most recent call last):
  File "/home/peekay/Documents/projects/django/deploy/techV2/techv2-venv/lib/python3.10/site-packages/requests/adapters.py", line 667, in send
    resp = conn.urlopen(
  File "/home/peekay/Documents/projects/django/deploy/techV2/techv2-venv/lib/python3.10/site-packages/urllib3/connectionpool.py", line 847, in urlopen
    retries = retries.increment(
  File "/home/peekay/Documents/projects/django/deploy/techV2/techv2-venv/lib/python3.10/site-packages/urllib3/util/retry.py", line 515, in increment
    raise MaxRetryError(_pool, url, reason) from reason  # type: ignore[arg-type]
urllib3.exceptions.MaxRetryError: HTTPSConnectionPool(host='sandbox.safaricom.co.ke', port=443): Max retries exceeded with url: /oauth/v1/generate?grant_type=client_credentials (Caused by NameResolutionError("<urllib3.connection.HTTPSConnection object at 0x7a553d524a30>: Failed to resolve 'sandbox.safaricom.co.ke' ([Errno -5] No address associated with hostname)"))

During handling of the above exception, another exception occurred:

Traceback (most recent call last):
  File "/home/peekay/Documents/projects/django/deploy/techV2/techv2-venv/lib/python3.10/site-packages/django/core/handlers/exception.py", line 55, in inner
    response = get_response(request)
  File "/home/peekay/Documents/projects/django/deploy/techV2/techv2-venv/lib/python3.10/site-packages/django/core/handlers/base.py", line 197, in _get_response
    response = wrapped_callback(request, *callback_args, **callback_kwargs)
  File "/home/peekay/Documents/projects/django/deploy/techV2/techv2-venv/lib/python3.10/site-packages/django/contrib/auth/decorators.py", line 23, in _wrapper_view
    return view_func(request, *args, **kwargs)
  File "/home/peekay/Documents/projects/django/deploy/techV2/techv2-venv/lib/python3.10/site-packages/django/views/decorators/csrf.py", line 56, in wrapper_view
    return view_func(*args, **kwargs)
  File "/home/peekay/Documents/projects/django/deploy/techV2/investor/views.py", line 783, in init_stk
    access_token = get_access_token()
  File "/home/peekay/Documents/projects/django/deploy/techV2/investor/views.py", line 749, in get_access_token
    r = requests.get(endpoint, auth=HTTPBasicAuth(consumer_key, consumer_secret))
  File "/home/peekay/Documents/projects/django/deploy/techV2/techv2-venv/lib/python3.10/site-packages/requests/api.py", line 73, in get
    return request("get", url, params=params, **kwargs)
  File "/home/peekay/Documents/projects/django/deploy/techV2/techv2-venv/lib/python3.10/site-packages/requests/api.py", line 59, in request
    return session.request(method=method, url=url, **kwargs)
  File "/home/peekay/Documents/projects/django/deploy/techV2/techv2-venv/lib/python3.10/site-packages/requests/sessions.py", line 589, in request
    resp = self.send(prep, **send_kwargs)
  File "/home/peekay/Documents/projects/django/deploy/techV2/techv2-venv/lib/python3.10/site-packages/requests/sessions.py", line 703, in send
    r = adapter.send(request, **kwargs)
  File "/home/peekay/Documents/projects/django/deploy/techV2/techv2-venv/lib/python3.10/site-packages/requests/adapters.py", line 700, in send
    raise ConnectionError(e, request=request)
requests.exceptions.ConnectionError: HTTPSConnectionPool(host='sandbox.safaricom.co.ke', port=443): Max retries exceeded with url: /oauth/v1/generate?grant_type=client_credentials (Caused by NameResolutionError("<urllib3.connection.HTTPSConnection object at 0x7a553d524a30>: Failed to resolve 'sandbox.safaricom.co.ke' ([Errno -5] No address associated with hostname)"))
Internal Server Error: /stkpush
Traceback (most recent call last):
  File "/home/peekay/Documents/projects/django/deploy/techV2/techv2-venv/lib/python3.10/site-packages/urllib3/connectionpool.py", line 793, in urlopen
    response = self._make_request(
  File "/home/peekay/Documents/projects/django/deploy/techV2/techv2-venv/lib/python3.10/site-packages/urllib3/connectionpool.py", line 537, in _make_request
    response = conn.getresponse()
  File "/home/peekay/Documents/projects/django/deploy/techV2/techv2-venv/lib/python3.10/site-packages/urllib3/connection.py", line 466, in getresponse
    httplib_response = super().getresponse()
  File "/usr/lib/python3.10/http/client.py", line 1375, in getresponse
    response.begin()
  File "/usr/lib/python3.10/http/client.py", line 318, in begin
    version, status, reason = self._read_status()
  File "/usr/lib/python3.10/http/client.py", line 287, in _read_status
    raise RemoteDisconnected("Remote end closed connection without"
http.client.RemoteDisconnected: Remote end closed connection without response

During handling of the above exception, another exception occurred:

Traceback (most recent call last):
  File "/home/peekay/Documents/projects/django/deploy/techV2/techv2-venv/lib/python3.10/site-packages/requests/adapters.py", line 667, in send
    resp = conn.urlopen(
  File "/home/peekay/Documents/projects/django/deploy/techV2/techv2-venv/lib/python3.10/site-packages/urllib3/connectionpool.py", line 847, in urlopen
    retries = retries.increment(
  File "/home/peekay/Documents/projects/django/deploy/techV2/techv2-venv/lib/python3.10/site-packages/urllib3/util/retry.py", line 470, in increment
    raise reraise(type(error), error, _stacktrace)
  File "/home/peekay/Documents/projects/django/deploy/techV2/techv2-venv/lib/python3.10/site-packages/urllib3/util/util.py", line 38, in reraise
    raise value.with_traceback(tb)
  File "/home/peekay/Documents/projects/django/deploy/techV2/techv2-venv/lib/python3.10/site-packages/urllib3/connectionpool.py", line 793, in urlopen
    response = self._make_request(
  File "/home/peekay/Documents/projects/django/deploy/techV2/techv2-venv/lib/python3.10/site-packages/urllib3/connectionpool.py", line 537, in _make_request
    response = conn.getresponse()
  File "/home/peekay/Documents/projects/django/deploy/techV2/techv2-venv/lib/python3.10/site-packages/urllib3/connection.py", line 466, in getresponse
    httplib_response = super().getresponse()
  File "/usr/lib/python3.10/http/client.py", line 1375, in getresponse
    response.begin()
  File "/usr/lib/python3.10/http/client.py", line 318, in begin
    version, status, reason = self._read_status()
  File "/usr/lib/python3.10/http/client.py", line 287, in _read_status
    raise RemoteDisconnected("Remote end closed connection without"
urllib3.exceptions.ProtocolError: ('Connection aborted.', RemoteDisconnected('Remote end closed connection without response'))

During handling of the above exception, another exception occurred:

Traceback (most recent call last):
  File "/home/peekay/Documents/projects/django/deploy/techV2/techv2-venv/lib/python3.10/site-packages/django/core/handlers/exception.py", line 55, in inner
    response = get_response(request)
  File "/home/peekay/Documents/projects/django/deploy/techV2/techv2-venv/lib/python3.10/site-packages/django/core/handlers/base.py", line 197, in _get_response
    response = wrapped_callback(request, *callback_args, **callback_kwargs)
  File "/home/peekay/Documents/projects/django/deploy/techV2/techv2-venv/lib/python3.10/site-packages/django/contrib/auth/decorators.py", line 23, in _wrapper_view
    return view_func(request, *args, **kwargs)
  File "/home/peekay/Documents/projects/django/deploy/techV2/techv2-venv/lib/python3.10/site-packages/django/views/decorators/csrf.py", line 56, in wrapper_view
    return view_func(*args, **kwargs)
  File "/home/peekay/Documents/projects/django/deploy/techV2/investor/views.py", line 783, in init_stk
    access_token = get_access_token()
  File "/home/peekay/Documents/projects/django/deploy/techV2/investor/views.py", line 749, in get_access_token
    r = requests.get(endpoint, auth=HTTPBasicAuth(consumer_key, consumer_secret))
  File "/home/peekay/Documents/projects/django/deploy/techV2/techv2-venv/lib/python3.10/site-packages/requests/api.py", line 73, in get
    return request("get", url, params=params, **kwargs)
  File "/home/peekay/Documents/projects/django/deploy/techV2/techv2-venv/lib/python3.10/site-packages/requests/api.py", line 59, in request
    return session.request(method=method, url=url, **kwargs)
  File "/home/peekay/Documents/projects/django/deploy/techV2/techv2-venv/lib/python3.10/site-packages/requests/sessions.py", line 589, in request
    resp = self.send(prep, **send_kwargs)
  File "/home/peekay/Documents/projects/django/deploy/techV2/techv2-venv/lib/python3.10/site-packages/requests/sessions.py", line 703, in send
    r = adapter.send(request, **kwargs)
  File "/home/peekay/Documents/projects/django/deploy/techV2/techv2-venv/lib/python3.10/site-packages/requests/adapters.py", line 682, in send
    raise ConnectionError(err, request=request)
requests.exceptions.ConnectionError: ('Connection aborted.', RemoteDisconnected('Remote end closed connection without response'))
Not Found: /favicon.ico
/home/peekay/Documents/projects/django/deploy/techV2/investor/views.py changed, reloading.
Watching for file changes with StatReloader
/home/peekay/Documents/projects/django/deploy/techV2/investor/views.py changed, reloading.
Watching for file changes with StatReloader
/home/peekay/Documents/projects/django/deploy/techV2/investor/views.py changed, reloading.
Watching for file changes with StatReloader
/home/peekay/Documents/projects/django/deploy/techV2/investor/views.py changed, reloading.
Watching for file changes with StatReloader
/home/peekay/Documents/projects/django/deploy/techV2/investor/views.py changed, reloading.
Watching for file changes with StatReloader
Not Found: /favicon.ico
/home/peekay/Documents/projects/django/deploy/techV2/investor/views.py changed, reloading.
Watching for file changes with StatReloader
Not Found: /favicon.ico
/home/peekay/Documents/projects/django/deploy/techV2/investor/models.py changed, reloading.
Watching for file changes with StatReloader
/home/peekay/Documents/projects/django/deploy/techV2/investor/views.py changed, reloading.
Watching for file changes with StatReloader
/home/peekay/Documents/projects/django/deploy/techV2/investor/views.py changed, reloading.
Watching for file changes with StatReloader
Watching for file changes with StatReloader
Watching for file changes with StatReloader
/home/peekay/Documents/projects/django/deploy/techV2/investor/views.py changed, reloading.
Watching for file changes with StatReloader
/home/peekay/Documents/projects/django/deploy/techV2/investor/utils.py changed, reloading.
Watching for file changes with StatReloader
/home/peekay/Documents/projects/django/deploy/techV2/investor/utils.py changed, reloading.
Watching for file changes with StatReloader
/home/peekay/Documents/projects/django/deploy/techV2/investor/views.py changed, reloading.
Watching for file changes with StatReloader
/home/peekay/Documents/projects/django/deploy/techV2/investor/views.py changed, reloading.
Watching for file changes with StatReloader
/home/peekay/Documents/projects/django/deploy/techV2/investor/views.py changed, reloading.
Watching for file changes with StatReloader
Internal Server Error: /stkpush
Traceback (most recent call last):
  File "/home/peekay/Documents/projects/django/deploy/techV2/techv2-venv/lib/python3.10/site-packages/django/core/handlers/exception.py", line 55, in inner
    response = get_response(request)
  File "/home/peekay/Documents/projects/django/deploy/techV2/techv2-venv/lib/python3.10/site-packages/django/core/handlers/base.py", line 197, in _get_response
    response = wrapped_callback(request, *callback_args, **callback_kwargs)
  File "/home/peekay/Documents/projects/django/deploy/techV2/techv2-venv/lib/python3.10/site-packages/django/contrib/auth/decorators.py", line 23, in _wrapper_view
    return view_func(request, *args, **kwargs)
  File "/home/peekay/Documents/projects/django/deploy/techV2/techv2-venv/lib/python3.10/site-packages/django/views/decorators/csrf.py", line 56, in wrapper_view
    return view_func(*args, **kwargs)
  File "/home/peekay/Documents/projects/django/deploy/techV2/investor/views.py", line 765, in init_stk
    access_token = get_access_token()
  File "/home/peekay/Documents/projects/django/deploy/techV2/investor/utils.py", line 28, in get_access_token
    r = requests.get(endpoint, auth=HTTPBasicAuth(consumer_key, consumer_secret))
NameError: name 'requests' is not defined
Internal Server Error: /stkpush
Traceback (most recent call last):
  File "/home/peekay/Documents/projects/django/deploy/techV2/techv2-venv/lib/python3.10/site-packages/django/core/handlers/exception.py", line 55, in inner
    response = get_response(request)
  File "/home/peekay/Documents/projects/django/deploy/techV2/techv2-venv/lib/python3.10/site-packages/django/core/handlers/base.py", line 197, in _get_response
    response = wrapped_callback(request, *callback_args, **callback_kwargs)
  File "/home/peekay/Documents/projects/django/deploy/techV2/techv2-venv/lib/python3.10/site-packages/django/contrib/auth/decorators.py", line 23, in _wrapper_view
    return view_func(request, *args, **kwargs)
  File "/home/peekay/Documents/projects/django/deploy/techV2/techv2-venv/lib/python3.10/site-packages/django/views/decorators/csrf.py", line 56, in wrapper_view
    return view_func(*args, **kwargs)
  File "/home/peekay/Documents/projects/django/deploy/techV2/investor/views.py", line 765, in init_stk
    access_token = get_access_token()
  File "/home/peekay/Documents/projects/django/deploy/techV2/investor/utils.py", line 28, in get_access_token
    r = requests.get(endpoint, auth=HTTPBasicAuth(consumer_key, consumer_secret))
NameError: name 'requests' is not defined
/home/peekay/Documents/projects/django/deploy/techV2/investor/utils.py changed, reloading.
Watching for file changes with StatReloader
Internal Server Error: /stkpush
Traceback (most recent call last):
  File "/home/peekay/Documents/projects/django/deploy/techV2/techv2-venv/lib/python3.10/site-packages/django/core/handlers/exception.py", line 55, in inner
    response = get_response(request)
  File "/home/peekay/Documents/projects/django/deploy/techV2/techv2-venv/lib/python3.10/site-packages/django/core/handlers/base.py", line 197, in _get_response
    response = wrapped_callback(request, *callback_args, **callback_kwargs)
  File "/home/peekay/Documents/projects/django/deploy/techV2/techv2-venv/lib/python3.10/site-packages/django/contrib/auth/decorators.py", line 23, in _wrapper_view
    return view_func(request, *args, **kwargs)
  File "/home/peekay/Documents/projects/django/deploy/techV2/techv2-venv/lib/python3.10/site-packages/django/views/decorators/csrf.py", line 56, in wrapper_view
    return view_func(*args, **kwargs)
  File "/home/peekay/Documents/projects/django/deploy/techV2/investor/views.py", line 765, in init_stk
    access_token = get_access_token()
  File "/home/peekay/Documents/projects/django/deploy/techV2/investor/utils.py", line 29, in get_access_token
    r = requests.get(endpoint, auth=HTTPBasicAuth(consumer_key, consumer_secret))
NameError: name 'HTTPBasicAuth' is not defined
/home/peekay/Documents/projects/django/deploy/techV2/investor/utils.py changed, reloading.
Watching for file changes with StatReloader
Watching for file changes with StatReloader
/home/peekay/Documents/projects/django/deploy/techV2/investor/views.py changed, reloading.
Watching for file changes with StatReloader
Watching for file changes with StatReloader
/home/peekay/Documents/projects/django/deploy/techV2/investor/views.py changed, reloading.
Watching for file changes with StatReloader
/home/peekay/Documents/projects/django/deploy/techV2/investor/views.py changed, reloading.
Watching for file changes with StatReloader
/home/peekay/Documents/projects/django/deploy/techV2/investor/views.py changed, reloading.
Watching for file changes with StatReloader
/home/peekay/Documents/projects/django/deploy/techV2/investor/views.py changed, reloading.
Watching for file changes with StatReloader
Watching for file changes with StatReloader
Internal Server Error: /stkpush
Traceback (most recent call last):
  File "/home/peekay/Documents/projects/django/deploy/techV2/techv2-venv/lib/python3.10/site-packages/urllib3/connection.py", line 198, in _new_conn
    sock = connection.create_connection(
  File "/home/peekay/Documents/projects/django/deploy/techV2/techv2-venv/lib/python3.10/site-packages/urllib3/util/connection.py", line 60, in create_connection
    for res in socket.getaddrinfo(host, port, family, socket.SOCK_STREAM):
  File "/usr/lib/python3.10/socket.py", line 955, in getaddrinfo
    for res in _socket.getaddrinfo(host, port, family, type, proto, flags):
socket.gaierror: [Errno -5] No address associated with hostname

The above exception was the direct cause of the following exception:

Traceback (most recent call last):
  File "/home/peekay/Documents/projects/django/deploy/techV2/techv2-venv/lib/python3.10/site-packages/urllib3/connectionpool.py", line 793, in urlopen
    response = self._make_request(
  File "/home/peekay/Documents/projects/django/deploy/techV2/techv2-venv/lib/python3.10/site-packages/urllib3/connectionpool.py", line 491, in _make_request
    raise new_e
  File "/home/peekay/Documents/projects/django/deploy/techV2/techv2-venv/lib/python3.10/site-packages/urllib3/connectionpool.py", line 467, in _make_request
    self._validate_conn(conn)
  File "/home/peekay/Documents/projects/django/deploy/techV2/techv2-venv/lib/python3.10/site-packages/urllib3/connectionpool.py", line 1099, in _validate_conn
    conn.connect()
  File "/home/peekay/Documents/projects/django/deploy/techV2/techv2-venv/lib/python3.10/site-packages/urllib3/connection.py", line 616, in connect
    self.sock = sock = self._new_conn()
  File "/home/peekay/Documents/projects/django/deploy/techV2/techv2-venv/lib/python3.10/site-packages/urllib3/connection.py", line 205, in _new_conn
    raise NameResolutionError(self.host, self, e) from e
urllib3.exceptions.NameResolutionError: <urllib3.connection.HTTPSConnection object at 0x7e9b979d97e0>: Failed to resolve 'sandbox.safaricom.co.ke' ([Errno -5] No address associated with hostname)

The above exception was the direct cause of the following exception:

Traceback (most recent call last):
  File "/home/peekay/Documents/projects/django/deploy/techV2/techv2-venv/lib/python3.10/site-packages/requests/adapters.py", line 667, in send
    resp = conn.urlopen(
  File "/home/peekay/Documents/projects/django/deploy/techV2/techv2-venv/lib/python3.10/site-packages/urllib3/connectionpool.py", line 847, in urlopen
    retries = retries.increment(
  File "/home/peekay/Documents/projects/django/deploy/techV2/techv2-venv/lib/python3.10/site-packages/urllib3/util/retry.py", line 515, in increment
    raise MaxRetryError(_pool, url, reason) from reason  # type: ignore[arg-type]
urllib3.exceptions.MaxRetryError: HTTPSConnectionPool(host='sandbox.safaricom.co.ke', port=443): Max retries exceeded with url: /oauth/v1/generate?grant_type=client_credentials (Caused by NameResolutionError("<urllib3.connection.HTTPSConnection object at 0x7e9b979d97e0>: Failed to resolve 'sandbox.safaricom.co.ke' ([Errno -5] No address associated with hostname)"))

During handling of the above exception, another exception occurred:

Traceback (most recent call last):
  File "/home/peekay/Documents/projects/django/deploy/techV2/techv2-venv/lib/python3.10/site-packages/django/core/handlers/exception.py", line 55, in inner
    response = get_response(request)
  File "/home/peekay/Documents/projects/django/deploy/techV2/techv2-venv/lib/python3.10/site-packages/django/core/handlers/base.py", line 197, in _get_response
    response = wrapped_callback(request, *callback_args, **callback_kwargs)
  File "/home/peekay/Documents/projects/django/deploy/techV2/techv2-venv/lib/python3.10/site-packages/django/contrib/auth/decorators.py", line 23, in _wrapper_view
    return view_func(request, *args, **kwargs)
  File "/home/peekay/Documents/projects/django/deploy/techV2/techv2-venv/lib/python3.10/site-packages/django/views/decorators/csrf.py", line 56, in wrapper_view
    return view_func(*args, **kwargs)
  File "/home/peekay/Documents/projects/django/deploy/techV2/investor/views.py", line 765, in init_stk
    access_token = get_access_token()
  File "/home/peekay/Documents/projects/django/deploy/techV2/investor/utils.py", line 33, in get_access_token
    r = requests.get(endpoint, auth=HTTPBasicAuth(consumer_key, consumer_secret))
  File "/home/peekay/Documents/projects/django/deploy/techV2/techv2-venv/lib/python3.10/site-packages/requests/api.py", line 73, in get
    return request("get", url, params=params, **kwargs)
  File "/home/peekay/Documents/projects/django/deploy/techV2/techv2-venv/lib/python3.10/site-packages/requests/api.py", line 59, in request
    return session.request(method=method, url=url, **kwargs)
  File "/home/peekay/Documents/projects/django/deploy/techV2/techv2-venv/lib/python3.10/site-packages/requests/sessions.py", line 589, in request
    resp = self.send(prep, **send_kwargs)
  File "/home/peekay/Documents/projects/django/deploy/techV2/techv2-venv/lib/python3.10/site-packages/requests/sessions.py", line 703, in send
    r = adapter.send(request, **kwargs)
  File "/home/peekay/Documents/projects/django/deploy/techV2/techv2-venv/lib/python3.10/site-packages/requests/adapters.py", line 700, in send
    raise ConnectionError(e, request=request)
requests.exceptions.ConnectionError: HTTPSConnectionPool(host='sandbox.safaricom.co.ke', port=443): Max retries exceeded with url: /oauth/v1/generate?grant_type=client_credentials (Caused by NameResolutionError("<urllib3.connection.HTTPSConnection object at 0x7e9b979d97e0>: Failed to resolve 'sandbox.safaricom.co.ke' ([Errno -5] No address associated with hostname)"))
Not Found: /favicon.ico
/home/peekay/Documents/projects/django/deploy/techV2/investor/models.py changed, reloading.
Watching for file changes with StatReloader
Not Found: /favicon.ico
/home/peekay/Documents/projects/django/deploy/techV2/investor/models.py changed, reloading.
Watching for file changes with StatReloader
Not Found: /favicon.ico
Not Found: /favicon.ico
Not Found: /favicon.ico
Not Found: /favicon.ico
Not Found: /favicon.ico
Not Found: /favicon.ico
Watching for file changes with StatReloader
Not Found: /dashboard/images/demo/pic1.jpg
Not Found: /dashboard/images/demo/pic2.jpg
Not Found: /dashboard/images/demo/pic3.jpg
Not Found: /dashboard/images/demo/pic4.jpg
Not Found: /dashboard/images/demo/pic8.jpg
Not Found: /dashboard/images/demo/pic5.jpg
Not Found: /dashboard/images/demo/pic6.jpg
Not Found: /dashboard/images/demo/pic7.jpg
Not Found: /favicon.ico
/home/peekay/Documents/projects/django/deploy/techV2/investor/views.py changed, reloading.
Watching for file changes with StatReloader
/home/peekay/Documents/projects/django/deploy/techV2/investor/views.py changed, reloading.
Watching for file changes with StatReloader
/home/peekay/Documents/projects/django/deploy/techV2/investor/views.py changed, reloading.
Watching for file changes with StatReloader
Watching for file changes with StatReloader
/home/peekay/Documents/projects/django/deploy/techV2/investor/models.py changed, reloading.
Watching for file changes with StatReloader
/home/peekay/Documents/projects/django/deploy/techV2/investor/views.py changed, reloading.
Watching for file changes with StatReloader
/home/peekay/Documents/projects/django/deploy/techV2/investor/views.py changed, reloading.
Watching for file changes with StatReloader
/home/peekay/Documents/projects/django/deploy/techV2/investor/views.py changed, reloading.
Watching for file changes with StatReloader
/home/peekay/Documents/projects/django/deploy/techV2/investor/views.py changed, reloading.
Watching for file changes with StatReloader
/home/peekay/Documents/projects/django/deploy/techV2/investor/views.py changed, reloading.
Watching for file changes with StatReloader
Watching for file changes with StatReloader
Not Found: /favicon.ico
Not Found: /favicon.ico
/home/peekay/Documents/projects/django/deploy/techV2/investor/views.py changed, reloading.
Watching for file changes with StatReloader
Not Found: /favicon.ico
/home/peekay/Documents/projects/django/deploy/techV2/investor/views.py changed, reloading.
Watching for file changes with StatReloader
/home/peekay/Documents/projects/django/deploy/techV2/investor/views.py changed, reloading.
Watching for file changes with StatReloader
Not Found: /dashboard/images/demo/pic1.jpg
Not Found: /dashboard/images/demo/pic4.jpg
Not Found: /dashboard/images/demo/pic8.jpg
Not Found: /dashboard/images/demo/pic3.jpg
Not Found: /dashboard/images/demo/pic5.jpg
Not Found: /dashboard/images/demo/pic2.jpg
Not Found: /dashboard/images/demo/pic7.jpg
Not Found: /dashboard/images/demo/pic6.jpg
Not Found: /favicon.ico
/home/peekay/Documents/projects/django/deploy/techV2/investor/views.py changed, reloading.
Watching for file changes with StatReloader
/home/peekay/Documents/projects/django/deploy/techV2/investor/views.py changed, reloading.
Watching for file changes with StatReloader
Method Not Allowed (GET): /callback
Method Not Allowed: /callback
Not Found: /favicon.ico
/home/peekay/Documents/projects/django/deploy/techV2/investor/views.py changed, reloading.
Watching for file changes with StatReloader
/home/peekay/Documents/projects/django/deploy/techV2/investor/views.py changed, reloading.
Watching for file changes with StatReloader
Watching for file changes with StatReloader
Not Found: /favicon.ico
Internal Server Error: /dashboard/
Traceback (most recent call last):
  File "/home/peekay/Documents/projects/django/deploy/techV2/techv2-venv/lib/python3.10/site-packages/django/core/handlers/exception.py", line 55, in inner
    response = get_response(request)
  File "/home/peekay/Documents/projects/django/deploy/techV2/techv2-venv/lib/python3.10/site-packages/django/core/handlers/base.py", line 197, in _get_response
    response = wrapped_callback(request, *callback_args, **callback_kwargs)
  File "/home/peekay/Documents/projects/django/deploy/techV2/techv2-venv/lib/python3.10/site-packages/django/contrib/auth/decorators.py", line 23, in _wrapper_view
    return view_func(request, *args, **kwargs)
  File "/home/peekay/Documents/projects/django/deploy/techV2/investor/views.py", line 139, in dashboard
    bonus = "{:,.2f}".format(UserAccount.objects.get(username=request.user).bonus)
  File "/home/peekay/Documents/projects/django/deploy/techV2/techv2-venv/lib/python3.10/site-packages/django/db/models/manager.py", line 87, in manager_method
    return getattr(self.get_queryset(), name)(*args, **kwargs)
  File "/home/peekay/Documents/projects/django/deploy/techV2/techv2-venv/lib/python3.10/site-packages/django/db/models/query.py", line 637, in get
    raise self.model.DoesNotExist(
investor.models.UserAccount.DoesNotExist: UserAccount matching query does not exist.
Not Found: /favicon.ico
Not Found: /dashboard/images/demo/pic2.jpg
Not Found: /dashboard/images/demo/pic1.jpg
Not Found: /dashboard/images/demo/pic3.jpg
Not Found: /dashboard/images/demo/pic5.jpg
Not Found: /dashboard/images/demo/pic4.jpg
Not Found: /dashboard/images/demo/pic7.jpg
Not Found: /dashboard/images/demo/pic8.jpg
Not Found: /dashboard/images/demo/pic6.jpg
Not Found: /favicon.ico
Not Found: /favicon.ico
Watching for file changes with StatReloader
Not Found: /favicon.ico
/home/peekay/Documents/projects/django/deploy/techV2/investor/views.py changed, reloading.
Watching for file changes with StatReloader
/home/peekay/Documents/projects/django/deploy/techV2/investor/views.py changed, reloading.
Watching for file changes with StatReloader
/home/peekay/Documents/projects/django/deploy/techV2/investor/views.py changed, reloading.
Watching for file changes with StatReloader
